Workbook

Sheet COMISION STAFF
E2: Fecha | F2: =NOW() -> 46324.461 | G2: Grupo | H2: S1 CASHMAX | J2: TLJ | L2: MATEO | M2: % DEVOLUCIÓN | N2: %FALTA META | O2: POR ASESOR
E3: PRODUCTIVIDAD | G3: ASIGNACIÓN | H3: =SUM(F5:F15) -> #N/A | J3: RECAUDO | L3: =SUM(H5:H15) -> #N/A | M3: =L3/H3 -> #N/A | N3: =(H3*9.5%)-L3 -> #N/A | O3: =N3/11 -> #N/A
B4: META | C4: CUMPLIMIENTO | D4: PERCENTIL | E4: Asesor | F4: Asignacion | G4: Cuentas | H4: Recaudo | I4: %_Meta | J4: $_Meta | K4: # GESTIONES | L4: Falta | M4: %_Aporte | N4: DOMINGO 1 | O4: DOMINGO 2 | P4: DOMINGO 3 | Q4: FESTIVO 1 | R4: R DOMINGO 1 | S4: R DOMINGO 2 | T4: R DOMINGO 3 | U4: FESTIVO | V4: FESTIVO 2
B5: 0.12 | C5: =M5/B5 -> #N/A | D5: =IF(C5>=0.95,"S",IF(C5>=0.9,"A",IF(C5>=0.8,"B",IF(C5>=0.7,"C",IF(C5>=0.6,"D","F"))))) -> #N/A | F5: =VLOOKUP(E5,'ASIGNACION RANKING'!D:AB,7,0)-N5-O5 -> #N/A | G5: =VLOOKUP(E5,'ASIGNACION RANKING'!D:AB,6,0) -> #N/A | H5: =VLOOKUP(E5,'ASIGNACION RANKING'!D:AB,11,0)-R5-S5 -> #N/A | I5: 0.15 | J5: =F5*I5 -> #N/A | K5: =VLOOKUP(E5,[1]ASIGNACION!AA1:AM55,13,0) -> #N/A | L5: =J5-H5 -> #N/A | M5: =H5/F5 -> #N/A | N5: =VLOOKUP(E5,'DOMINGO 1'!D:AB,7,0) -> #N/A | O5: =VLOOKUP(E5,'DOMINGO 2'!D:AB,7,0) -> #N/A | P5: 0 | Q5: =VLOOKUP(E5,'FESTIVO 1'!D:AB,7,0) -> #N/A | R5: =VLOOKUP(E5,'DOMINGO 1'!D:AB,11,0) -> #N/A | S5: =VLOOKUP(E5,'DOMINGO 2'!D:AB,11,0) -> #N/A | T5: 0
B6: 0.12 | C6: =M6/B6 -> #N/A | D6: =IF(C6>=0.95,"S",IF(C6>=0.9,"A",IF(C6>=0.8,"B",IF(C6>=0.7,"C",IF(C6>=0.6,"D","F"))))) -> #N/A | F6: =VLOOKUP(E6,'ASIGNACION RANKING'!D:AB,7,0)-N6-O6 -> #N/A | G6: =VLOOKUP(E6,'ASIGNACION RANKING'!D:AB,6,0) -> #N/A | H6: =VLOOKUP(E6,'ASIGNACION RANKING'!D:AB,11,0)-R6-S6 -> #N/A | I6: 0.15 | J6: =F6*I6 -> #N/A | K6: =VLOOKUP(E6,[1]ASIGNACION!AA2:AM56,13,0) -> #N/A | L6: =J6-H6 -> #N/A | M6: =H6/F6 -> #N/A | N6: =VLOOKUP(E6,'DOMINGO 1'!D:AB,7,0) -> #N/A | O6: =VLOOKUP(E6,'DOMINGO 2'!D:AB,7,0) -> #N/A | P6: =VLOOKUP(E6,'DOMINGO 3'!D:AB,7,0) -> #N/A | Q6: 0 | R6: =VLOOKUP(E6,'DOMINGO 1'!D:AB,11,0) -> #N/A | S6: =VLOOKUP(E6,'DOMINGO 2'!D:AB,11,0) -> #N/A | T6: =VLOOKUP(E6,'DOMINGO 3'!D:AB,11,0) -> #N/A
B7: 0.12 | C7: =M7/B7 -> #N/A | D7: =IF(C7>=0.95,"S",IF(C7>=0.9,"A",IF(C7>=0.8,"B",IF(C7>=0.7,"C",IF(C7>=0.6,"D","F"))))) -> #N/A | F7: =VLOOKUP(E7,'ASIGNACION RANKING'!D:AB,7,0)-N7-O7 -> #N/A | G7: =VLOOKUP(E7,'ASIGNACION RANKING'!D:AB,6,0) -> #N/A | H7: =VLOOKUP(E7,'ASIGNACION RANKING'!D:AB,11,0)-R7-S7 -> #N/A | I7: 0.15 | J7: =F7*I7 -> #N/A | K7: =VLOOKUP(E7,[1]ASIGNACION!AA3:AM57,13,0) -> #N/A | L7: =J7-H7 -> #N/A | M7: =H7/F7 -> #N/A | N7: =VLOOKUP(E7,'DOMINGO 1'!D:AB,7,0) -> #N/A | O7: =VLOOKUP(E7,'DOMINGO 2'!D:AB,7,0) -> #N/A | P7: =VLOOKUP(E7,'DOMINGO 3'!D:AB,7,0) -> #N/A | Q7: =VLOOKUP(E7,'FESTIVO 1'!D:AB,7,0) -> #N/A | R7: =VLOOKUP(E7,'DOMINGO 1'!D:AB,11,0) -> #N/A | S7: =VLOOKUP(E7,'DOMINGO 2'!D:AB,11,0) -> #N/A | T7: =VLOOKUP(E7,'DOMINGO 3'!D:AB,11,0) -> #N/A
B8: 0.12 | C8: =M8/B8 -> #N/A | D8: =IF(C8>=0.95,"S",IF(C8>=0.9,"A",IF(C8>=0.8,"B",IF(C8>=0.7,"C",IF(C8>=0.6,"D","F"))))) -> #N/A | F8: =VLOOKUP(E8,'ASIGNACION RANKING'!D:AB,7,0)-N8-O8 -> #N/A | G8: =VLOOKUP(E8,'ASIGNACION RANKING'!D:AB,6,0) -> #N/A | H8: =VLOOKUP(E8,'ASIGNACION RANKING'!D:AB,11,0)-R8-S8 -> #N/A | I8: 0.15 | J8: =F8*I8 -> #N/A | K8: =VLOOKUP(E8,[1]ASIGNACION!AA4:AM58,13,0) -> #N/A | L8: =J8-H8 -> #N/A | M8: =H8/F8 -> #N/A | N8: =VLOOKUP(E8,'DOMINGO 1'!D:AB,7,0) -> #N/A | O8: =VLOOKUP(E8,'DOMINGO 2'!D:AB,7,0) -> #N/A | P8: =VLOOKUP(E8,'DOMINGO 3'!D:AB,7,0) -> #N/A | Q8: =VLOOKUP(E8,'FESTIVO 1'!D:AB,7,0) -> #N/A | R8: =VLOOKUP(E8,'DOMINGO 1'!D:AB,11,0) -> #N/A | S8: =VLOOKUP(E8,'DOMINGO 2'!D:AB,11,0) -> #N/A | T8: =VLOOKUP(E8,'DOMINGO 3'!D:AB,11,0) -> #N/A
B9: 0.12 | C9: =M9/B9 -> #N/A | D9: =IF(C9>=0.95,"S",IF(C9>=0.9,"A",IF(C9>=0.8,"B",IF(C9>=0.7,"C",IF(C9>=0.6,"D","F"))))) -> #N/A | F9: =VLOOKUP(E9,'ASIGNACION RANKING'!D:AB,7,0)-N9-O9 -> #N/A | G9: =VLOOKUP(E9,'ASIGNACION RANKING'!D:AB,6,0) -> #N/A | H9: =VLOOKUP(E9,'ASIGNACION RANKING'!D:AB,11,0)-R9-S9 -> #N/A | I9: 0.15 | J9: =F9*I9 -> #N/A | K9: =VLOOKUP(E9,[1]ASIGNACION!AA5:AM59,13,0) -> #N/A | L9: =J9-H9 -> #N/A | M9: =H9/F9 -> #N/A | N9: =VLOOKUP(E9,'DOMINGO 1'!D:AB,7,0) -> #N/A | O9: =VLOOKUP(E9,'DOMINGO 2'!D:AB,7,0) -> #N/A | P9: =VLOOKUP(E9,'DOMINGO 3'!D:AB,7,0) -> #N/A | Q9: =VLOOKUP(E9,'FESTIVO 1'!D:AB,7,0) -> #N/A | R9: =VLOOKUP(E9,'DOMINGO 1'!D:AB,11,0) -> #N/A | S9: =VLOOKUP(E9,'DOMINGO 2'!D:AB,11,0) -> #N/A | T9: =VLOOKUP(E9,'DOMINGO 3'!D:AB,11,0) -> #N/A
B10: 0.12 | C10: =M10/B10 -> #N/A | D10: =IF(C10>=0.95,"S",IF(C10>=0.9,"A",IF(C10>=0.8,"B",IF(C10>=0.7,"C",IF(C10>=0.6,"D","F"))))) -> #N/A | F10: =VLOOKUP(E10,'ASIGNACION RANKING'!D:AB,7,0)-N10-O10 -> #N/A | G10: =VLOOKUP(E10,'ASIGNACION RANKING'!D:AB,6,0) -> #N/A | H10: =VLOOKUP(E10,'ASIGNACION RANKING'!D:AB,11,0)-R10-S10 -> #N/A | I10: 0.15 | J10: =F10*I10 -> #N/A | K10: =VLOOKUP(E10,[1]ASIGNACION!AA1:AM60,13,0) -> #N/A | L10: =J10-H10 -> #N/A | M10: =H10/F10 -> #N/A | N10: =VLOOKUP(E10,'DOMINGO 1'!D:AB,7,0) -> #N/A | O10: =VLOOKUP(E10,'DOMINGO 2'!D:AB,7,0) -> #N/A | P10: =VLOOKUP(E10,'DOMINGO 3'!D:AB,7,0) -> #N/A | Q10: =VLOOKUP(E10,'FESTIVO 1'!D:AB,7,0) -> #N/A | R10: =VLOOKUP(E10,'DOMINGO 1'!D:AB,11,0) -> #N/A | S10: =VLOOKUP(E10,'DOMINGO 2'!D:AB,11,0) -> #N/A | T10: =VLOOKUP(E10,'DOMINGO 3'!D:AB,11,0) -> #N/A
B11: 0.12 | C11: =M11/B11 -> #N/A | D11: =IF(C11>=0.95,"S",IF(C11>=0.9,"A",IF(C11>=0.8,"B",IF(C11>=0.7,"C",IF(C11>=0.6,"D","F"))))) -> #N/A | F11: =VLOOKUP(E11,'ASIGNACION RANKING'!D:AB,7,0)-N11-O11 -> #N/A | G11: =VLOOKUP(E11,'ASIGNACION RANKING'!D:AB,6,0) -> #N/A | H11: =VLOOKUP(E11,'ASIGNACION RANKING'!D:AB,11,0)-R11-S11 -> #N/A | I11: 0.15 | J11: =F11*I11 -> #N/A | K11: =VLOOKUP(E11,[1]ASIGNACION!AA7:AM61,13,0) -> #N/A | L11: =J11-H11 -> #N/A | M11: =H11/F11 -> #N/A | N11: =VLOOKUP(E11,'DOMINGO 1'!D:AB,7,0) -> #N/A | O11: =VLOOKUP(E11,'DOMINGO 2'!D:AB,7,0) -> #N/A | P11: 0 | Q11: =VLOOKUP(E11,'FESTIVO 1'!D:AB,7,0) -> #N/A | R11: =VLOOKUP(E11,'DOMINGO 1'!D:AB,11,0) -> #N/A | S11: =VLOOKUP(E11,'DOMINGO 2'!D:AB,11,0) -> #N/A | T11: 0
B12: 0.12 | C12: =M12/B12 -> #N/A | D12: =IF(C12>=0.95,"S",IF(C12>=0.9,"A",IF(C12>=0.8,"B",IF(C12>=0.7,"C",IF(C12>=0.6,"D","F"))))) -> #N/A | F12: =VLOOKUP(E12,'ASIGNACION RANKING'!D:AB,7,0)-N12-O12 -> #N/A | G12: =VLOOKUP(E12,'ASIGNACION RANKING'!D:AB,6,0) -> #N/A | H12: =VLOOKUP(E12,'ASIGNACION RANKING'!D:AB,11,0)-R12-S12 -> #N/A | I12: 0.15 | J12: =F12*I12 -> #N/A | K12: =VLOOKUP(E12,[1]ASIGNACION!AA8:AM62,13,0) -> #N/A | L12: =J12-H12 -> #N/A | M12: =H12/F12 -> #N/A | N12: =VLOOKUP(E12,'DOMINGO 1'!D:AB,7,0) -> #N/A | O12: =VLOOKUP(E12,'DOMINGO 2'!D:AB,7,0) -> #N/A | P12: =VLOOKUP(E12,'DOMINGO 3'!D:AB,7,0) -> #N/A | Q12: =VLOOKUP(E12,'FESTIVO 1'!D:AB,7,0) -> #N/A | R12: =VLOOKUP(E12,'DOMINGO 1'!D:AB,11,0) -> #N/A | S12: =VLOOKUP(E12,'DOMINGO 2'!D:AB,11,0) -> #N/A | T12: =VLOOKUP(E12,'DOMINGO 3'!D:AB,11,0) -> #N/A
B13: 0.12 | C13: =M13/B13 -> #N/A | D13: =IF(C13>=0.95,"S",IF(C13>=0.9,"A",IF(C13>=0.8,"B",IF(C13>=0.7,"C",IF(C13>=0.6,"D","F"))))) -> #N/A | F13: =VLOOKUP(E13,'ASIGNACION RANKING'!D:AB,7,0)-N13-O13 -> #N/A | G13: =VLOOKUP(E13,'ASIGNACION RANKING'!D:AB,6,0) -> #N/A | H13: =VLOOKUP(E13,'ASIGNACION RANKING'!D:AB,11,0)-R13-S13 -> #N/A | I13: 0.15 | J13: =F13*I13 -> #N/A | K13: =VLOOKUP(E13,[1]ASIGNACION!AA9:AM63,13,0) -> #N/A | L13: =J13-H13 -> #N/A | M13: =H13/F13 -> #N/A | N13: =VLOOKUP(E13,'DOMINGO 1'!D:AB,7,0) -> #N/A | O13: =VLOOKUP(E13,'DOMINGO 2'!D:AB,7,0) -> #N/A | P13: =VLOOKUP(E13,'DOMINGO 3'!D:AB,7,0) -> #N/A | Q13: 0 | R13: =VLOOKUP(E13,'DOMINGO 1'!D:AB,11,0) -> #N/A | S13: =VLOOKUP(E13,'DOMINGO 2'!D:AB,11,0) -> #N/A | T13: =VLOOKUP(E13,'DOMINGO 3'!D:AB,11,0) -> #N/A
B14: 0.12 | C14: =M14/B14 -> #N/A | D14: =IF(C14>=0.95,"S",IF(C14>=0.9,"A",IF(C14>=0.8,"B",IF(C14>=0.7,"C",IF(C14>=0.6,"D","F"))))) -> #N/A | F14: =VLOOKUP(E14,'ASIGNACION RANKING'!D:AB,7,0)-N14-O14 -> #N/A | G14: =VLOOKUP(E14,'ASIGNACION RANKING'!D:AB,6,0) -> #N/A | H14: =VLOOKUP(E14,'ASIGNACION RANKING'!D:AB,11,0)-R14-S14 -> #N/A | I14: 0.15 | J14: =F14*I14 -> #N/A | K14: =VLOOKUP(E14,[1]ASIGNACION!AA10:AM64,13,0) -> #N/A | L14: =J14-H14 -> #N/A | M14: =H14/F14 -> #N/A | N14: =VLOOKUP(E14,'DOMINGO 1'!D:AB,7,0) -> #N/A | O14: =VLOOKUP(E14,'DOMINGO 2'!D:AB,7,0) -> #N/A | P14: =VLOOKUP(E14,'DOMINGO 3'!D:AB,7,0) -> #N/A | Q14: =VLOOKUP(E14,'FESTIVO 1'!D:AB,7,0) -> #N/A | R14: =VLOOKUP(E14,'DOMINGO 1'!D:AB,11,0) -> #N/A | S14: =VLOOKUP(E14,'DOMINGO 2'!D:AB,11,0) -> #N/A | T14: =VLOOKUP(E14,'DOMINGO 3'!D:AB,11,0) -> #N/A
B15: 0.12 | C15: =M15/B15 -> #N/A | D15: =IF(C15>=0.95,"S",IF(C15>=0.9,"A",IF(C15>=0.8,"B",IF(C15>=0.7,"C",IF(C15>=0.6,"D","F"))))) -> #N/A | F15: =VLOOKUP(E15,'ASIGNACION RANKING'!D:AB,7,0)-N15-O15 -> #N/A | G15: =VLOOKUP(E15,'ASIGNACION RANKING'!D:AB,6,0) -> #N/A | H15: =VLOOKUP(E15,'ASIGNACION RANKING'!D:AB,11,0)-R15-S15 -> #N/A | I15: 0.15 | J15: =F15*I15 -> #N/A | L15: =J15-H15 -> #N/A | M15: =H15/F15 -> #N/A | N15: =VLOOKUP(E15,'DOMINGO 1'!D:AB,7,0) -> #N/A | O15: =VLOOKUP(E15,'DOMINGO 2'!D:AB,7,0) -> #N/A | P15: =VLOOKUP(E15,'DOMINGO 3'!D:AB,7,0) -> #N/A | Q15: =VLOOKUP(E15,'FESTIVO 1'!D:AB,7,0) -> #N/A | R15: =VLOOKUP(E15,'DOMINGO 1'!D:AB,11,0) -> #N/A | S15: =VLOOKUP(E15,'DOMINGO 2'!D:AB,11,0) -> #N/A | T15: =VLOOKUP(E15,'DOMINGO 3'!D:AB,11,0) -> #N/A
E17: Fecha | F17: =NOW() -> 46324.461 | G17: Grupo | H17: S2 CASHMAX | J17: TLJ | L17: MATEO | M17: % DEVOLUCIÓN | N17: %FALTA META | O17: POR ASESOR
E18: PRODUCTIVIDAD | G18: ASIGNACIÓN | H18: =SUM(F20:F29) -> #N/A | J18: RECUADO | L18: =SUM(H20:H29) -> #N/A | M18: =L18/H18 -> #N/A | N18: =(H18*1.2%)-L18 -> #N/A | O18: =N18/10 -> #N/A
B19: META | C19: CUMPLIMIENTO | D19: PERCENTIL | E19: Asesor | F19: Asignacion | G19: Cuentas | H19: Recaudo | I19: %_Meta | J19: $_Meta | K19: # GESTIONES | L19: Falta | M19: %_Aporte | N19: DOMINGO 1 | O19: DOMINGO 2 | P19: DOMINGO 3 | Q19: FESTIVO 1 | R19: FESTIVO 2
B20: 0.012 | C20: =M20/B20 -> #N/A | D20: =IF(C20>=0.95,"S",IF(C20>=0.9,"A",IF(C20>=0.8,"B",IF(C20>=0.7,"C",IF(C20>=0.6,"D","F"))))) -> #N/A | E20: A0120(CRISTIAN RODRIGUEZ ) | F20: =VLOOKUP(E20,'ASIGNACION RANKING'!D:AB,7,0)-N20-O20 -> #N/A | G20: =VLOOKUP(E20,'ASIGNACION RANKING'!D:AB,6,0) -> #N/A | H20: =VLOOKUP(E20,'ASIGNACION RANKING'!D:AB,11,0) -> #N/A | I20: 0.018 | J20: =F20*I20 -> #N/A | K20: =VLOOKUP(E20,[1]ASIGNACION!AA1:AM75,13,0) -> #N/A | L20: =J20-H20 -> #N/A | M20: =H20/F20 -> #N/A | N20: =VLOOKUP(E20,'DOMINGO 1'!D:AB,7,0) -> #N/A | O20: =VLOOKUP(E20,'DOMINGO 2'!D:AB,7,0) -> #N/A | P20: =VLOOKUP(E20,'DOMINGO 3'!D:AB,7,0) -> #N/A | Q20: =VLOOKUP(E20,'FESTIVO 1'!D:AB,7,0) -> #N/A
B21: 0.012 | C21: =M21/B21 -> #N/A | D21: =IF(C21>=0.95,"S",IF(C21>=0.9,"A",IF(C21>=0.8,"B",IF(C21>=0.7,"C",IF(C21>=0.6,"D","F"))))) -> #N/A | E21: A0068(JENNY MENDIETA) | F21: =VLOOKUP(E21,'ASIGNACION RANKING'!D:AB,7,0)-N21-O21 -> #N/A | G21: =VLOOKUP(E21,'ASIGNACION RANKING'!D:AB,6,0) -> #N/A | H21: =VLOOKUP(E21,'ASIGNACION RANKING'!D:AB,11,0) -> #N/A | I21: 0.018 | J21: =F21*I21 -> #N/A | K21: =VLOOKUP(E21,[1]ASIGNACION!AA2:AM76,13,0) -> #N/A | L21: =J21-H21 -> #N/A | M21: =H21/F21 -> #N/A | N21: =VLOOKUP(E21,'DOMINGO 1'!D:AB,7,0) -> #N/A | O21: =VLOOKUP(E21,'DOMINGO 2'!D:AB,7,0) -> #N/A | P21: =VLOOKUP(E21,'DOMINGO 3'!D:AB,7,0) -> #N/A | Q21: =VLOOKUP(E21,'FESTIVO 1'!D:AB,7,0) -> #N/A
B22: 0.012 | C22: =M22/B22 -> #N/A | D22: =IF(C22>=0.95,"S",IF(C22>=0.9,"A",IF(C22>=0.8,"B",IF(C22>=0.7,"C",IF(C22>=0.6,"D","F"))))) -> #N/A | E22: A03290(JOHAN OJEDA) | F22: =VLOOKUP(E22,'ASIGNACION RANKING'!D:AB,7,0)-N22-O22 -> #N/A | G22: =VLOOKUP(E22,'ASIGNACION RANKING'!D:AB,6,0) -> #N/A | H22: =VLOOKUP(E22,'ASIGNACION RANKING'!D:AB,11,0) -> #N/A | I22: 0.018 | J22: =F22*I22 -> #N/A | K22: =VLOOKUP(E22,[1]ASIGNACION!AA3:AM77,13,0) -> #N/A | L22: =J22-H22 -> #N/A | M22: =H22/F22 -> #N/A | N22: =VLOOKUP(E22,'DOMINGO 1'!D:AB,7,0) -> #N/A | O22: =VLOOKUP(E22,'DOMINGO 2'!D:AB,7,0) -> #N/A | P22: =VLOOKUP(E22,'DOMINGO 3'!D:AB,7,0) -> #N/A | Q22: =VLOOKUP(E22,'FESTIVO 1'!D:AB,7,0) -> #N/A
B23: 0.012 | C23: =M23/B23 -> #N/A | D23: =IF(C23>=0.95,"S",IF(C23>=0.9,"A",IF(C23>=0.8,"B",IF(C23>=0.7,"C",IF(C23>=0.6,"D","F"))))) -> #N/A | E23: A0364(JOSE VERA) | F23: =VLOOKUP(E23,'ASIGNACION RANKING'!D:AB,7,0)-N23-O23 -> #N/A | G23: =VLOOKUP(E23,'ASIGNACION RANKING'!D:AB,6,0) -> #N/A | H23: =VLOOKUP(E23,'ASIGNACION RANKING'!D:AB,11,0) -> #N/A | I23: 0.018 | J23: =F23*I23 -> #N/A | K23: =VLOOKUP(E23,[1]ASIGNACION!AA4:AM78,13,0) -> #N/A | L23: =J23-H23 -> #N/A | M23: =H23/F23 -> #N/A | N23: =VLOOKUP(E23,'DOMINGO 1'!D:AB,7,0) -> #N/A | O23: =VLOOKUP(E23,'DOMINGO 2'!D:AB,7,0) -> #N/A | P23: =VLOOKUP(E23,'DOMINGO 3'!D:AB,7,0) -> #N/A | Q23: =VLOOKUP(E23,'FESTIVO 1'!D:AB,7,0) -> #N/A
B24: 0.012 | C24: =M24/B24 -> #N/A | D24: =IF(C24>=0.95,"S",IF(C24>=0.9,"A",IF(C24>=0.8,"B",IF(C24>=0.7,"C",IF(C24>=0.6,"D","F"))))) -> #N/A | E24: A0340(KAFFYR PUERTAS) | F24: =VLOOKUP(E24,'ASIGNACION RANKING'!D:AB,7,0)-N24-O24 -> #N/A | G24: =VLOOKUP(E24,'ASIGNACION RANKING'!D:AB,6,0) -> #N/A | H24: =VLOOKUP(E24,'ASIGNACION RANKING'!D:AB,11,0) -> #N/A | I24: 0.018 | J24: =F24*I24 -> #N/A | K24: =VLOOKUP(E24,[1]ASIGNACION!AA5:AM79,13,0) -> #N/A | L24: =J24-H24 -> #N/A | M24: =H24/F24 -> #N/A | N24: =VLOOKUP(E24,'DOMINGO 1'!D:AB,7,0) -> #N/A | O24: =VLOOKUP(E24,'DOMINGO 2'!D:AB,7,0) -> #N/A | P24: =VLOOKUP(E24,'DOMINGO 3'!D:AB,7,0) -> #N/A | Q24: =VLOOKUP(E24,'FESTIVO 1'!D:AB,7,0) -> #N/A
B25: 0.012 | C25: =M25/B25 -> #N/A | D25: =IF(C25>=0.95,"S",IF(C25>=0.9,"A",IF(C25>=0.8,"B",IF(C25>=0.7,"C",IF(C25>=0.6,"D","F"))))) -> #N/A | E25: A0053(LAURA RUBIANO) | F25: =VLOOKUP(E25,'ASIGNACION RANKING'!D:AB,7,0)-N25-O25 -> #N/A | G25: =VLOOKUP(E25,'ASIGNACION RANKING'!D:AB,6,0) -> #N/A | H25: =VLOOKUP(E25,'ASIGNACION RANKING'!D:AB,11,0) -> #N/A | I25: 0.018 | J25: =F25*I25 -> #N/A | K25: =VLOOKUP(E25,[1]ASIGNACION!AA6:AM80,13,0) -> #N/A | L25: =J25-H25 -> #N/A | M25: =H25/F25 -> #N/A | N25: =VLOOKUP(E25,'DOMINGO 1'!D:AB,7,0) -> #N/A | O25: =VLOOKUP(E25,'DOMINGO 2'!D:AB,7,0) -> #N/A | P25: =VLOOKUP(E25,'DOMINGO 3'!D:AB,7,0) -> #N/A | Q25: =VLOOKUP(E25,'FESTIVO 1'!D:AB,7,0) -> #N/A
B26: 0.012 | C26: =M26/B26 -> #N/A | D26: =IF(C26>=0.95,"S",IF(C26>=0.9,"A",IF(C26>=0.8,"B",IF(C26>=0.7,"C",IF(C26>=0.6,"D","F"))))) -> #N/A | E26: A0360(MARCELA VALDERRAMA) | F26: =VLOOKUP(E26,'ASIGNACION RANKING'!D:AB,7,0)-N26-O26 -> #N/A | G26: =VLOOKUP(E26,'ASIGNACION RANKING'!D:AB,6,0) -> #N/A | H26: =VLOOKUP(E26,'ASIGNACION RANKING'!D:AB,11,0) -> #N/A | I26: 0.018 | J26: =F26*I26 -> #N/A | K26: =VLOOKUP(E26,[1]ASIGNACION!AA7:AM81,13,0) -> #N/A | L26: =J26-H26 -> #N/A | M26: =H26/F26 -> #N/A | N26: =VLOOKUP(E26,'DOMINGO 1'!D:AB,7,0) -> #N/A | O26: =VLOOKUP(E26,'DOMINGO 2'!D:AB,7,0) -> #N/A | P26: =VLOOKUP(E26,'DOMINGO 3'!D:AB,7,0) -> #N/A | Q26: =VLOOKUP(E26,'FESTIVO 1'!D:AB,7,0) -> #N/A
B27: 0.012 | C27: =M27/B27 -> #N/A | D27: =IF(C27>=0.95,"S",IF(C27>=0.9,"A",IF(C27>=0.8,"B",IF(C27>=0.7,"C",IF(C27>=0.6,"D","F"))))) -> #N/A | E27: A0315(MATEO PINTO) | F27: =VLOOKUP(E27,'ASIGNACION RANKING'!D:AB,7,0)-N27-O27 -> #N/A | G27: =VLOOKUP(E27,'ASIGNACION RANKING'!D:AB,6,0) -> #N/A | H27: =VLOOKUP(E27,'ASIGNACION RANKING'!D:AB,11,0) -> #N/A | I27: 0.018 | J27: =F27*I27 -> #N/A | K27: =VLOOKUP(E27,[1]ASIGNACION!AA8:AM82,13,0) -> #N/A | L27: =J27-H27 -> #N/A | M27: =H27/F27 -> #N/A | N27: =VLOOKUP(E27,'DOMINGO 1'!D:AB,7,0) -> #N/A | O27: =VLOOKUP(E27,'DOMINGO 2'!D:AB,7,0) -> #N/A | P27: =VLOOKUP(E27,'DOMINGO 3'!D:AB,7,0) -> #N/A | Q27: =VLOOKUP(E27,'FESTIVO 1'!D:AB,7,0) -> #N/A
B28: 0.012 | C28: =M28/B28 -> #N/A | D28: =IF(C28>=0.95,"S",IF(C28>=0.9,"A",IF(C28>=0.8,"B",IF(C28>=0.7,"C",IF(C28>=0.6,"D","F"))))) -> #N/A | E28: A0135(PAULA RODRIGUEZ ) | F28: =VLOOKUP(E28,'ASIGNACION RANKING'!D:AB,7,0)-N28-O28 -> #N/A | G28: =VLOOKUP(E28,'ASIGNACION RANKING'!D:AB,6,0) -> #N/A | H28: =VLOOKUP(E28,'ASIGNACION RANKING'!D:AB,11,0) -> #N/A | I28: 0.018 | J28: =F28*I28 -> #N/A | K28: =VLOOKUP(E28,[1]ASIGNACION!AA9:AM83,13,0) -> #N/A | L28: =J28-H28 -> #N/A | M28: =H28/F28 -> #N/A | N28: =VLOOKUP(E28,'DOMINGO 1'!D:AB,7,0) -> #N/A | O28: =VLOOKUP(E28,'DOMINGO 2'!D:AB,7,0) -> #N/A | P28: =VLOOKUP(E28,'DOMINGO 3'!D:AB,7,0) -> #N/A | Q28: =VLOOKUP(E28,'FESTIVO 1'!D:AB,7,0) -> #N/A
B29: 0.012 | C29: =M29/B29 -> #N/A | D29: =IF(C29>=0.95,"S",IF(C29>=0.9,"A",IF(C29>=0.8,"B",IF(C29>=0.7,"C",IF(C29>=0.6,"D","F"))))) -> #N/A | E29: A0217(SEBASTIAN BARRIOS) | F29: =VLOOKUP(E29,'ASIGNACION RANKING'!D:AB,7,0)-N29-O29 -> #N/A | G29: =VLOOKUP(E29,'ASIGNACION RANKING'!D:AB,6,0) -> #N/A | H29: =VLOOKUP(E29,'ASIGNACION RANKING'!D:AB,11,0) -> #N/A | I29: 0.018 | J29: =F29*I29 -> #N/A | K29: =VLOOKUP(E29,[1]ASIGNACION!AA9:AM82,13,0) -> #N/A | L29: =J29-H29 -> #N/A | M29: =H29/F29 -> #N/A | N29: =VLOOKUP(E29,'DOMINGO 1'!D:AB,7,0) -> #N/A | O29: =VLOOKUP(E29,'DOMINGO 2'!D:AB,7,0) -> #N/A | P29: =VLOOKUP(E29,'DOMINGO 3'!D:AB,7,0) -> #N/A | Q29: =VLOOKUP(E29,'FESTIVO 1'!D:AB,7,0) -> #N/A
E31: Fecha | F31: =NOW() -> 46324.461 | G31: Grupo | H31: M1 CASHMAX | J31: TLJ | L31: MATEO | M31: % DEVOLUCIÓN | N31: %FALTA META | O31: POR ASESOR
E32: PRODUCTIVIDAD | G32: ASIGNACIÓN | H32: =SUM(F34:F41) -> #N/A | J32: RECUADO | L32: =SUM(H34:H41) -> #N/A | M32: =L32/H32 -> #N/A | N32: =(H32*0.11%)-L32 -> #N/A | O32: =N32/7 -> #N/A
B33: META | C33: CUMPLIMIENTO | D33: PERCENTIL | E33: Asesor | F33: Asignacion | G33: Cuentas | H33: Recaudo | I33: %_Meta | J33: $_Meta | K33: # GESTIONES | L33: Falta | M33: %_Aporte | N33: DOMINGO 1 | O33: DOMINGO 2 | P33: DOMINGO 3 | Q33: FESTIVO 1 | R33: FESTIVO 2
B34: 0.0015 | C34: =M34/B34 -> #N/A | D34: =IF(C34>=0.95,"S",IF(C34>=0.9,"A",IF(C34>=0.8,"B",IF(C34>=0.7,"C",IF(C34>=0.6,"D","F"))))) -> #N/A | F34: =VLOOKUP(E34,'ASIGNACION RANKING'!D:AB,7,0)-N34-O34 -> #N/A | G34: =VLOOKUP(E34,'ASIGNACION RANKING'!D:AB,6,0) -> #N/A | H34: =VLOOKUP(E34,'ASIGNACION RANKING'!D:AB,11,0) -> #N/A | I34: 0.002 | J34: =F34*I34 -> #N/A | K34: =VLOOKUP(E34,[1]ASIGNACION!AA1:AM85,13,0) -> #N/A | L34: =J34-H34 -> #N/A | M34: =H34/F34 -> #N/A | N34: =VLOOKUP(E34,'DOMINGO 1'!D:AB,7,0) -> #N/A | O34: =VLOOKUP(E34,'DOMINGO 2'!D:AB,7,0) -> #N/A | P34: =VLOOKUP(E34,'DOMINGO 3'!D:AB,7,0) -> #N/A | Q34: =VLOOKUP(E34,'FESTIVO 1'!D:AB,7,0) -> #N/A
B35: 0.0015 | C35: =M35/B35 -> #N/A | D35: =IF(C35>=0.95,"S",IF(C35>=0.9,"A",IF(C35>=0.8,"B",IF(C35>=0.7,"C",IF(C35>=0.6,"D","F"))))) -> #N/A | F35: =VLOOKUP(E35,'ASIGNACION RANKING'!D:AB,7,0)-N35-O35 -> #N/A | G35: =VLOOKUP(E35,'ASIGNACION RANKING'!D:AB,6,0) -> #N/A | H35: =VLOOKUP(E35,'ASIGNACION RANKING'!D:AB,11,0) -> #N/A | I35: 0.002 | J35: =F35*I35 -> #N/A | K35: =VLOOKUP(E35,[1]ASIGNACION!AA2:AM86,13,0) -> #N/A | L35: =J35-H35 -> #N/A | M35: =H35/F35 -> #N/A | N35: =VLOOKUP(E35,'DOMINGO 1'!D:AB,7,0) -> #N/A | O35: =VLOOKUP(E35,'DOMINGO 2'!D:AB,7,0) -> #N/A | P35: 0 | Q35: =VLOOKUP(E35,'FESTIVO 1'!D:AB,7,0) -> #N/A
B36: 0.0015 | C36: =M36/B36 -> #N/A | D36: =IF(C36>=0.95,"S",IF(C36>=0.9,"A",IF(C36>=0.8,"B",IF(C36>=0.7,"C",IF(C36>=0.6,"D","F"))))) -> #N/A | F36: =VLOOKUP(E36,'ASIGNACION RANKING'!D:AB,7,0)-N36-O36 -> #N/A | G36: =VLOOKUP(E36,'ASIGNACION RANKING'!D:AB,6,0) -> #N/A | H36: =VLOOKUP(E36,'ASIGNACION RANKING'!D:AB,11,0) -> #N/A | I36: 0.002 | J36: =F36*I36 -> #N/A | K36: =VLOOKUP(E36,[1]ASIGNACION!AA3:AM86,13,0) -> #N/A | L36: =J36-H36 -> #N/A | M36: =H36/F36 -> #N/A | N36: =VLOOKUP(E36,'DOMINGO 1'!D:AB,7,0) -> #N/A | O36: =VLOOKUP(E36,'DOMINGO 2'!D:AB,7,0) -> #N/A | P36: =VLOOKUP(E36,'DOMINGO 3'!D:AB,7,0) -> #N/A | Q36: =VLOOKUP(E36,'FESTIVO 1'!D:AB,7,0) -> #N/A
B37: 0.0015 | C37: =M37/B37 -> #N/A | D37: =IF(C37>=0.95,"S",IF(C37>=0.9,"A",IF(C37>=0.8,"B",IF(C37>=0.7,"C",IF(C37>=0.6,"D","F"))))) -> #N/A | F37: =VLOOKUP(E37,'ASIGNACION RANKING'!D:AB,7,0)-N37-O37 -> #N/A | G37: =VLOOKUP(E37,'ASIGNACION RANKING'!D:AB,6,0) -> #N/A | H37: =VLOOKUP(E37,'ASIGNACION RANKING'!D:AB,11,0) -> #N/A | I37: 0.002 | J37: =F37*I37 -> #N/A | K37: =VLOOKUP(E37,[1]ASIGNACION!AA4:AM86,13,0) -> #N/A | L37: =J37-H37 -> #N/A | M37: =H37/F37 -> #N/A | N37: =VLOOKUP(E37,'DOMINGO 1'!D:AB,7,0) -> #N/A | O37: =VLOOKUP(E37,'DOMINGO 2'!D:AB,7,0) -> #N/A | P37: =VLOOKUP(E37,'DOMINGO 3'!D:AB,7,0) -> #N/A | Q37: 0
B38: 0.0015 | C38: =M38/B38 -> #N/A | D38: =IF(C38>=0.95,"S",IF(C38>=0.9,"A",IF(C38>=0.8,"B",IF(C38>=0.7,"C",IF(C38>=0.6,"D","F"))))) -> #N/A | F38: =VLOOKUP(E38,'ASIGNACION RANKING'!D:AB,7,0)-N38-O38 -> #N/A | G38: =VLOOKUP(E38,'ASIGNACION RANKING'!D:AB,6,0) -> #N/A | H38: =VLOOKUP(E38,'ASIGNACION RANKING'!D:AB,11,0) -> #N/A | I38: 0.002 | J38: =F38*I38 -> #N/A | K38: =VLOOKUP(E38,[1]ASIGNACION!AA5:AM86,13,0) -> #N/A | L38: =J38-H38 -> #N/A | M38: =H38/F38 -> #N/A | N38: =VLOOKUP(E38,'DOMINGO 1'!D:AB,7,0) -> #N/A | O38: =VLOOKUP(E38,'DOMINGO 2'!D:AB,7,0) -> #N/A | P38: 0 | Q38: =VLOOKUP(E38,'FESTIVO 1'!D:AB,7,0) -> #N/A
B39: 0.0015 | C39: =M39/B39 -> #DIV/0! | D39: =IF(C39>=0.95,"S",IF(C39>=0.9,"A",IF(C39>=0.8,"B",IF(C39>=0.7,"C",IF(C39>=0.6,"D","F"))))) -> #DIV/0! | K39: =VLOOKUP(E39,[1]ASIGNACION!AA6:AM86,13,0) -> #N/A | L39: =J39-H39 -> 0 | M39: =H39/F39 -> #DIV/0! | N39: =VLOOKUP(E39,'DOMINGO 1'!D:AB,7,0) -> #N/A | O39: =VLOOKUP(E39,'DOMINGO 2'!D:AB,7,0) -> #N/A | P39: =VLOOKUP(E39,'DOMINGO 3'!D:AB,7,0) -> #N/A | Q39: =VLOOKUP(E39,'FESTIVO 1'!D:AB,7,0) -> #N/A
B40: 0.0015 | C40: =M40/B40 -> #DIV/0! | D40: =IF(C40>=0.95,"S",IF(C40>=0.9,"A",IF(C40>=0.8,"B",IF(C40>=0.7,"C",IF(C40>=0.6,"D","F"))))) -> #DIV/0! | L40: =J40-H40 -> 0 | M40: =H40/F40 -> #DIV/0! | N40: =VLOOKUP(E40,'DOMINGO 1'!D:AB,7,0) -> #N/A | O40: =VLOOKUP(E40,'DOMINGO 2'!D:AB,7,0) -> #N/A | P40: =VLOOKUP(E40,'DOMINGO 3'!D:AB,7,0) -> #N/A | Q40: 0
B41: 0.0015 | C41: =M41/B41 -> #DIV/0! | D41: =IF(C41>=0.95,"S",IF(C41>=0.9,"A",IF(C41>=0.8,"B",IF(C41>=0.7,"C",IF(C41>=0.6,"D","F"))))) -> #DIV/0! | K41: =VLOOKUP(E41,[1]ASIGNACION!AA7:AM86,13,0) -> #N/A | L41: =J41-H41 -> 0 | M41: =H41/F41 -> #DIV/0! | N41: =VLOOKUP(E41,'DOMINGO 1'!D:AB,7,0) -> #N/A | O41: =VLOOKUP(E41,'DOMINGO 2'!D:AB,7,0) -> #N/A | P41: =VLOOKUP(E41,'DOMINGO 3'!D:AB,7,0) -> #N/A | Q41: =VLOOKUP(E41,'FESTIVO 1'!D:AB,7,0) -> #N/A
D43: PORCENTAJE | E43: PERCENTILES | F43: SIGNIFICA | Q43: S1
D44: 0.95 | E44: S | F44: PILAR, ARRASTRA LA CIFRA DE MANERA POSITIVA | Q44: % DE RECUPERACION | R44: COMISION | S44: PISO
...

Sheet COMISIONES
A1: SEGMENTO | B1: APLICACIÓN | C1: NOMBRE SISTEMA | D1: EJECUTIVO | E1: CC | F1: TLJ | G1: TL | H1: CUENTAS ASIGNADAS | I1: MONTO DE PEDIDOS EN BASE | J1: MONTO RECUPERADO | K1: DOMINGO 1 | L1: DOMINGO 2 | M1: PAGOS DOMINGO1 | N1: PAGOS DOMINGO2 | O1: ALL MONTO PEDIDOS EN BASE | P1: ALL MONTO RECUPERADO | Q1: % DE RETORNO | R1: BONO | S1: BONOS DIARIOS | T1: DESCUENTOS | U1: TOTAL BONUS
A2: S2 | B2: CASHMAX | C2: A0120(CRISTIAN RODRIGUEZ ) | F2: MATEO CANO | G2: JOSE SANCHEZ | H2: =VLOOKUP(C2,'ASIGNACION RANKING'!D:AB,6,0) -> #N/A | I2: =VLOOKUP(C2,'ASIGNACION RANKING'!D:AB,7,0) -> #N/A | J2: =VLOOKUP(C2,'ASIGNACION RANKING'!D:AB,11,0) -> #N/A | K2: =VLOOKUP(C2,'DOMINGO 1'!D:AB,7,0) -> #N/A | L2: =VLOOKUP(C2,'DOMINGO 2'!D:AB,7,0) -> #N/A | M2: =VLOOKUP(C2,'DOMINGO 1'!D:AB,11,0) -> #N/A | N2: =VLOOKUP(C2,'DOMINGO 2'!D:AB,11,0) -> #N/A | O2: =I2-K2-L2 -> #N/A | P2: =J2-M2-N2 -> #N/A | Q2: =P2/O2 -> #N/A | R2: =VLOOKUP(C2,RANKING!E:O,9,0) -> #N/A
A3: S2 | B3: CASHMAX | C3: A0068(JENNY MENDIETA) | F3: MATEO CANO | G3: JOSE SANCHEZ | H3: =VLOOKUP(C3,'ASIGNACION RANKING'!D:AB,6,0) -> #N/A | I3: =VLOOKUP(C3,'ASIGNACION RANKING'!D:AB,7,0) -> #N/A | J3: =VLOOKUP(C3,'ASIGNACION RANKING'!D:AB,11,0) -> #N/A | K3: =VLOOKUP(C3,'DOMINGO 1'!D:AB,7,0) -> #N/A | L3: =VLOOKUP(C3,'DOMINGO 2'!D:AB,7,0) -> #N/A | M3: =VLOOKUP(C3,'DOMINGO 1'!D:AB,11,0) -> #N/A | N3: =VLOOKUP(C3,'DOMINGO 2'!D:AB,11,0) -> #N/A | O3: =I3-K3-L3 -> #N/A | P3: =J3-M3-N3 -> #N/A | Q3: =P3/O3 -> #N/A | R3: =VLOOKUP(C3,RANKING!E:O,9,0) -> #N/A
A4: S2 | B4: CASHMAX | C4: A03290(JOHAN OJEDA) | F4: MATEO CANO | G4: JOSE SANCHEZ | H4: =VLOOKUP(C4,'ASIGNACION RANKING'!D:AB,6,0) -> #N/A | I4: =VLOOKUP(C4,'ASIGNACION RANKING'!D:AB,7,0) -> #N/A | J4: =VLOOKUP(C4,'ASIGNACION RANKING'!D:AB,11,0) -> #N/A | K4: =VLOOKUP(C4,'DOMINGO 1'!D:AB,7,0) -> #N/A | L4: =VLOOKUP(C4,'DOMINGO 2'!D:AB,7,0) -> #N/A | M4: =VLOOKUP(C4,'DOMINGO 1'!D:AB,11,0) -> #N/A | N4: =VLOOKUP(C4,'DOMINGO 2'!D:AB,11,0) -> #N/A | O4: =I4-K4-L4 -> #N/A | P4: =J4-M4-N4 -> #N/A | Q4: =P4/O4 -> #N/A | R4: =VLOOKUP(C4,RANKING!E:O,9,0) -> #N/A
A5: S2 | B5: CASHMAX | C5: A0364(JOSE VERA) | F5: MATEO CANO | G5: JOSE SANCHEZ | H5: =VLOOKUP(C5,'ASIGNACION RANKING'!D:AB,6,0) -> #N/A | I5: =VLOOKUP(C5,'ASIGNACION RANKING'!D:AB,7,0) -> #N/A | J5: =VLOOKUP(C5,'ASIGNACION RANKING'!D:AB,11,0) -> #N/A | K5: =VLOOKUP(C5,'DOMINGO 1'!D:AB,7,0) -> #N/A | L5: =VLOOKUP(C5,'DOMINGO 2'!D:AB,7,0) -> #N/A | M5: =VLOOKUP(C5,'DOMINGO 1'!D:AB,11,0) -> #N/A | N5: =VLOOKUP(C5,'DOMINGO 2'!D:AB,11,0) -> #N/A | O5: =I5-K5-L5 -> #N/A | P5: =J5-M5-N5 -> #N/A | Q5: =P5/O5 -> #N/A | R5: =VLOOKUP(C5,RANKING!E:O,9,0) -> #N/A
A6: S2 | B6: CASHMAX | C6: A0340(KAFFYR PUERTAS) | F6: MATEO CANO | G6: JOSE SANCHEZ | H6: =VLOOKUP(C6,'ASIGNACION RANKING'!D:AB,6,0) -> #N/A | I6: =VLOOKUP(C6,'ASIGNACION RANKING'!D:AB,7,0) -> #N/A | J6: =VLOOKUP(C6,'ASIGNACION RANKING'!D:AB,11,0) -> #N/A | K6: =VLOOKUP(C6,'DOMINGO 1'!D:AB,7,0) -> #N/A | L6: =VLOOKUP(C6,'DOMINGO 2'!D:AB,7,0) -> #N/A | M6: =VLOOKUP(C6,'DOMINGO 1'!D:AB,11,0) -> #N/A | N6: =VLOOKUP(C6,'DOMINGO 2'!D:AB,11,0) -> #N/A | O6: =I6-K6-L6 -> #N/A | P6: =J6-M6-N6 -> #N/A | Q6: =P6/O6 -> #N/A | R6: =VLOOKUP(C6,RANKING!E:O,9,0) -> #N/A
A7: S2 | B7: CASHMAX | C7: A0053(LAURA RUBIANO) | F7: MATEO CANO | G7: JOSE SANCHEZ | H7: =VLOOKUP(C7,'ASIGNACION RANKING'!D:AB,6,0) -> #N/A | I7: =VLOOKUP(C7,'ASIGNACION RANKING'!D:AB,7,0) -> #N/A | J7: =VLOOKUP(C7,'ASIGNACION RANKING'!D:AB,11,0) -> #N/A | K7: =VLOOKUP(C7,'DOMINGO 1'!D:AB,7,0) -> #N/A | L7: =VLOOKUP(C7,'DOMINGO 2'!D:AB,7,0) -> #N/A | M7: =VLOOKUP(C7,'DOMINGO 1'!D:AB,11,0) -> #N/A | N7: =VLOOKUP(C7,'DOMINGO 2'!D:AB,11,0) -> #N/A | O7: =I7-K7-L7 -> #N/A | P7: =J7-M7-N7 -> #N/A | Q7: =P7/O7 -> #N/A | R7: =VLOOKUP(C7,RANKING!E:O,9,0) -> #N/A
A8: S2 | B8: CASHMAX | C8: A0360(MARCELA VALDERRAMA) | F8: MATEO CANO | G8: JOSE SANCHEZ | H8: =VLOOKUP(C8,'ASIGNACION RANKING'!D:AB,6,0) -> #N/A | I8: =VLOOKUP(C8,'ASIGNACION RANKING'!D:AB,7,0) -> #N/A | J8: =VLOOKUP(C8,'ASIGNACION RANKING'!D:AB,11,0) -> #N/A | K8: =VLOOKUP(C8,'DOMINGO 1'!D:AB,7,0) -> #N/A | L8: =VLOOKUP(C8,'DOMINGO 2'!D:AB,7,0) -> #N/A | M8: =VLOOKUP(C8,'DOMINGO 1'!D:AB,11,0) -> #N/A | N8: =VLOOKUP(C8,'DOMINGO 2'!D:AB,11,0) -> #N/A | O8: =I8-K8-L8 -> #N/A | P8: =J8-M8-N8 -> #N/A | Q8: =P8/O8 -> #N/A | R8: =VLOOKUP(C8,RANKING!E:O,9,0) -> #N/A
A9: S2 | B9: CASHMAX | C9: A0315(MATEO PINTO) | F9: MATEO CANO | G9: JOSE SANCHEZ | H9: =VLOOKUP(C9,'ASIGNACION RANKING'!D:AB,6,0) -> #N/A | I9: =VLOOKUP(C9,'ASIGNACION RANKING'!D:AB,7,0) -> #N/A | J9: =VLOOKUP(C9,'ASIGNACION RANKING'!D:AB,11,0) -> #N/A | K9: =VLOOKUP(C9,'DOMINGO 1'!D:AB,7,0) -> #N/A | L9: =VLOOKUP(C9,'DOMINGO 2'!D:AB,7,0) -> #N/A | M9: =VLOOKUP(C9,'DOMINGO 1'!D:AB,11,0) -> #N/A | N9: =VLOOKUP(C9,'DOMINGO 2'!D:AB,11,0) -> #N/A | O9: =I9-K9-L9 -> #N/A | P9: =J9-M9-N9 -> #N/A | Q9: =P9/O9 -> #N/A | R9: =VLOOKUP(C9,RANKING!E:O,9,0) -> #N/A
A10: S2 | B10: CASHMAX | C10: A0135(PAULA RODRIGUEZ ) | F10: MATEO CANO | G10: JOSE SANCHEZ | H10: =VLOOKUP(C10,'ASIGNACION RANKING'!D:AB,6,0) -> #N/A | I10: =VLOOKUP(C10,'ASIGNACION RANKING'!D:AB,7,0) -> #N/A | J10: =VLOOKUP(C10,'ASIGNACION RANKING'!D:AB,11,0) -> #N/A | K10: =VLOOKUP(C10,'DOMINGO 1'!D:AB,7,0) -> #N/A | L10: =VLOOKUP(C10,'DOMINGO 2'!D:AB,7,0) -> #N/A | M10: =VLOOKUP(C10,'DOMINGO 1'!D:AB,11,0) -> #N/A | N10: =VLOOKUP(C10,'DOMINGO 2'!D:AB,11,0) -> #N/A | O10: =I10-K10-L10 -> #N/A | P10: =J10-M10-N10 -> #N/A | Q10: =P10/O10 -> #N/A | R10: =VLOOKUP(C10,RANKING!E:O,9,0) -> #N/A
A11: S2 | B11: CASHMAX | C11: A0217(SEBASTIAN BARRIOS) | F11: MATEO CANO | G11: JOSE SANCHEZ | H11: =VLOOKUP(C11,'ASIGNACION RANKING'!D:AB,6,0) -> #N/A | I11: =VLOOKUP(C11,'ASIGNACION RANKING'!D:AB,7,0) -> #N/A | J11: =VLOOKUP(C11,'ASIGNACION RANKING'!D:AB,11,0) -> #N/A | K11: =VLOOKUP(C11,'DOMINGO 1'!D:AB,7,0) -> #N/A | L11: =VLOOKUP(C11,'DOMINGO 2'!D:AB,7,0) -> #N/A | M11: =VLOOKUP(C11,'DOMINGO 1'!D:AB,11,0) -> #N/A | N11: =VLOOKUP(C11,'DOMINGO 2'!D:AB,11,0) -> #N/A | O11: =I11-K11-L11 -> #N/A | P11: =J11-M11-N11 -> #N/A | Q11: =P11/O11 -> #N/A | R11: =VLOOKUP(C11,RANKING!E:O,9,0) -> #N/A
A12: M2 | B12: CASHMAX | C12: A0325(DAYANA QUILINDO) | F12: MATEO CANO | G12: JOSE SANCHEZ | H12: =VLOOKUP(C12,'ASIGNACION RANKING'!D:AB,6,0) -> 935 | I12: =VLOOKUP(C12,'ASIGNACION RANKING'!D:AB,7,0) -> 1897052 | J12: =VLOOKUP(C12,'ASIGNACION RANKING'!D:AB,11,0) -> 150727 | K12: =VLOOKUP(C12,'DOMINGO 1'!D:AB,7,0) -> 122758 | L12: =VLOOKUP(C12,'DOMINGO 2'!D:AB,7,0) -> 162651 | M12: =VLOOKUP(C12,'DOMINGO 1'!D:AB,11,0) -> 4090 | N12: =VLOOKUP(C12,'DOMINGO 2'!D:AB,11,0) -> 4019 | O12: =I12-K12-L12 -> 1611643 | P12: =J12-M12-N12 -> 142618 | Q12: =P12/O12 -> 0.088492303 | R12: =VLOOKUP(C12,RANKING!E:O,9,0) -> B6
A13: M2 | B13: CASHMAX | C13: A0314(JASBLEIDY MARTINEZ) | F13: MATEO CANO | G13: JOSE SANCHEZ | H13: =VLOOKUP(C13,'ASIGNACION RANKING'!D:AB,6,0) -> #N/A | I13: =VLOOKUP(C13,'ASIGNACION RANKING'!D:AB,7,0) -> #N/A | J13: =VLOOKUP(C13,'ASIGNACION RANKING'!D:AB,11,0) -> #N/A | K13: =VLOOKUP(C13,'DOMINGO 1'!D:AB,7,0) -> #N/A | L13: =VLOOKUP(C13,'DOMINGO 2'!D:AB,7,0) -> #N/A | M13: =VLOOKUP(C13,'DOMINGO 1'!D:AB,11,0) -> #N/A | N13: =VLOOKUP(C13,'DOMINGO 2'!D:AB,11,0) -> #N/A | O13: =I13-K13-L13 -> #N/A | P13: =J13-M13-N13 -> #N/A | Q13: =P13/O13 -> #N/A | R13: =VLOOKUP(C13,RANKING!E:O,9,0) -> #N/A
A14: M2 | B14: CASHMAX | C14: A0099(NESLY SOSA) | F14: MATEO CANO | G14: JOSE SANCHEZ | H14: =VLOOKUP(C14,'ASIGNACION RANKING'!D:AB,6,0) -> #N/A | I14: =VLOOKUP(C14,'ASIGNACION RANKING'!D:AB,7,0) -> #N/A | J14: =VLOOKUP(C14,'ASIGNACION RANKING'!D:AB,11,0) -> #N/A | K14: =VLOOKUP(C14,'DOMINGO 1'!D:AB,7,0) -> #N/A | L14: =VLOOKUP(C14,'DOMINGO 2'!D:AB,7,0) -> #N/A | M14: =VLOOKUP(C14,'DOMINGO 1'!D:AB,11,0) -> #N/A | N14: =VLOOKUP(C14,'DOMINGO 2'!D:AB,11,0) -> #N/A | O14: =I14-K14-L14 -> #N/A | P14: =J14-M14-N14 -> #N/A | Q14: =P14/O14 -> #N/A | R14: =VLOOKUP(C14,RANKING!E:O,9,0) -> #N/A
A15: S1 | B15: OKDINERO | C15: A0258(CRIS URREGO) | F15: GINA VARONI | G15: JOSE SANCHEZ | H15: =VLOOKUP(C15,'ASIGNACION RANKING'!D:AB,6,0) -> 928 | I15: =VLOOKUP(C15,'ASIGNACION RANKING'!D:AB,7,0) -> 1784363 | J15: =VLOOKUP(C15,'ASIGNACION RANKING'!D:AB,11,0) -> 150166 | K15: =VLOOKUP(C15,'DOMINGO 1'!D:AB,7,0) -> 148155 | L15: =VLOOKUP(C15,'DOMINGO 2'!D:AB,7,0) -> 135241 | M15: =VLOOKUP(C15,'DOMINGO 1'!D:AB,11,0) -> 3898 | N15: =VLOOKUP(C15,'DOMINGO 2'!D:AB,11,0) -> 6698 | O15: =I15-K15-L15 -> 1500967 | P15: =J15-M15-N15 -> 139570 | Q15: =P15/O15 -> 0.092986721 | R15: =VLOOKUP(C15,RANKING!E:O,9,0) -> B3 | S15: 10000
A16: S1 | B16: OKDINERO | C16: A0221(DAVID GOMEZ) | F16: GINA VARONI | G16: JOSE SANCHEZ | H16: =VLOOKUP(C16,'ASIGNACION RANKING'!D:AB,6,0) -> 892 | I16: =VLOOKUP(C16,'ASIGNACION RANKING'!D:AB,7,0) -> 1699596 | J16: =VLOOKUP(C16,'ASIGNACION RANKING'!D:AB,11,0) -> 162632 | K16: =VLOOKUP(C16,'DOMINGO 1'!D:AB,7,0) -> 130494 | L16: =VLOOKUP(C16,'DOMINGO 2'!D:AB,7,0) -> 116669 | M16: =VLOOKUP(C16,'DOMINGO 1'!D:AB,11,0) -> 17387 | N16: =VLOOKUP(C16,'DOMINGO 2'!D:AB,11,0) -> 680 | O16: =I16-K16-L16 -> 1452433 | P16: =J16-M16-N16 -> 144565 | Q16: =P16/O16 -> 0.099532991 | R16: =VLOOKUP(C16,RANKING!E:O,9,0) -> B2
A17: S1 | B17: OKDINERO | C17: A0288(FABIAN STIVEN) | F17: GINA VARONI | G17: JOSE SANCHEZ | H17: =VLOOKUP(C17,'ASIGNACION RANKING'!D:AB,6,0) -> 960 | I17: =VLOOKUP(C17,'ASIGNACION RANKING'!D:AB,7,0) -> 1684427 | J17: =VLOOKUP(C17,'ASIGNACION RANKING'!D:AB,11,0) -> 146554 | K17: =VLOOKUP(C17,'DOMINGO 1'!D:AB,7,0) -> 144616 | L17: =VLOOKUP(C17,'DOMINGO 2'!D:AB,7,0) -> 104116 | M17: =VLOOKUP(C17,'DOMINGO 1'!D:AB,11,0) -> 5765 | N17: =VLOOKUP(C17,'DOMINGO 2'!D:AB,11,0) -> 3989 | O17: =I17-K17-L17 -> 1435695 | P17: =J17-M17-N17 -> 136800 | Q17: =P17/O17 -> 0.095284862 | R17: =VLOOKUP(C17,RANKING!E:O,9,0) -> B2
A18: S1 | B18: OKDINERO | C18: A0208(JAVIER RINCON) | F18: GINA VARONI | G18: JOSE SANCHEZ | H18: =VLOOKUP(C18,'ASIGNACION RANKING'!D:AB,6,0) -> #N/A | I18: =VLOOKUP(C18,'ASIGNACION RANKING'!D:AB,7,0) -> #N/A | J18: =VLOOKUP(C18,'ASIGNACION RANKING'!D:AB,11,0) -> #N/A | K18: =VLOOKUP(C18,'DOMINGO 1'!D:AB,7,0) -> #N/A | L18: =VLOOKUP(C18,'DOMINGO 2'!D:AB,7,0) -> #N/A | M18: =VLOOKUP(C18,'DOMINGO 1'!D:AB,11,0) -> #N/A | N18: =VLOOKUP(C18,'DOMINGO 2'!D:AB,11,0) -> #N/A | O18: =I18-K18-L18 -> #N/A | P18: =J18-M18-N18 -> #N/A | Q18: =P18/O18 -> #N/A | R18: =VLOOKUP(C18,RANKING!E:O,9,0) -> #N/A
A19: S1 | B19: OKDINERO | C19: A0399(JHULIET VARGAS) | F19: GINA VARONI | G19: JOSE SANCHEZ | H19: =VLOOKUP(C19,'ASIGNACION RANKING'!D:AB,6,0) -> 231 | I19: =VLOOKUP(C19,'ASIGNACION RANKING'!D:AB,7,0) -> 356300 | J19: =VLOOKUP(C19,'ASIGNACION RANKING'!D:AB,11,0) -> 16051 | K19: =VLOOKUP(C19,'DOMINGO 1'!D:AB,7,0) -> 119843 | L19: =VLOOKUP(C19,'DOMINGO 2'!D:AB,7,0) -> #N/A | M19: =VLOOKUP(C19,'DOMINGO 1'!D:AB,11,0) -> 6611 | N19: =VLOOKUP(C19,'DOMINGO 2'!D:AB,11,0) -> #N/A | O19: =I19-K19-L19 -> #N/A | P19: =J19-M19-N19 -> #N/A | Q19: =P19/O19 -> #N/A | R19: =VLOOKUP(C19,RANKING!E:O,9,0) -> #N/A
A20: S1 | B20: OKDINERO | C20: A0128(LEIDY TORRES) | F20: GINA VARONI | G20: JOSE SANCHEZ | H20: =VLOOKUP(C20,'ASIGNACION RANKING'!D:AB,6,0) -> 1002 | I20: =VLOOKUP(C20,'ASIGNACION RANKING'!D:AB,7,0) -> 1734384 | J20: =VLOOKUP(C20,'ASIGNACION RANKING'!D:AB,11,0) -> 134395 | K20: =VLOOKUP(C20,'DOMINGO 1'!D:AB,7,0) -> 125992 | L20: =VLOOKUP(C20,'DOMINGO 2'!D:AB,7,0) -> 136031 | M20: =VLOOKUP(C20,'DOMINGO 1'!D:AB,11,0) -> 6647 | N20: =VLOOKUP(C20,'DOMINGO 2'!D:AB,11,0) -> 2252 | O20: =I20-K20-L20 -> 1472361 | P20: =J20-M20-N20 -> 125496 | Q20: =P20/O20 -> 0.085234531 | R20: =VLOOKUP(C20,RANKING!E:O,9,0) -> B7 | S20: 30000
A21: S1 | B21: OKDINERO | C21: A0388(MICHAEL BARRIOS) | F21: GINA VARONI | G21: JOSE SANCHEZ | H21: =VLOOKUP(C21,'ASIGNACION RANKING'!D:AB,6,0) -> 1011 | I21: =VLOOKUP(C21,'ASIGNACION RANKING'!D:AB,7,0) -> 2047451 | J21: =VLOOKUP(C21,'ASIGNACION RANKING'!D:AB,11,0) -> 129409 | K21: =VLOOKUP(C21,'DOMINGO 1'!D:AB,7,0) -> 155182 | L21: =VLOOKUP(C21,'DOMINGO 2'!D:AB,7,0) -> 153195 | M21: =VLOOKUP(C21,'DOMINGO 1'!D:AB,11,0) -> 5161 | N21: =VLOOKUP(C21,'DOMINGO 2'!D:AB,11,0) -> 5798 | O21: =I21-K21-L21 -> 1739074 | P21: =J21-M21-N21 -> 118450 | Q21: =P21/O21 -> 0.06811096 | R21: =VLOOKUP(C21,RANKING!E:O,9,0) -> C0 | S21: 10000
A22: S1 | B22: OKDINERO | C22: 0445(MIGUEL ZULETA) | F22: GINA VARONI | G22: JOSE SANCHEZ | H22: =VLOOKUP(C22,'ASIGNACION RANKING'!D:AB,6,0) -> #N/A | I22: =VLOOKUP(C22,'ASIGNACION RANKING'!D:AB,7,0) -> #N/A | J22: =VLOOKUP(C22,'ASIGNACION RANKING'!D:AB,11,0) -> #N/A | K22: =VLOOKUP(C22,'DOMINGO 1'!D:AB,7,0) -> #N/A | L22: =VLOOKUP(C22,'DOMINGO 2'!D:AB,7,0) -> #N/A | M22: =VLOOKUP(C22,'DOMINGO 1'!D:AB,11,0) -> #N/A | N22: =VLOOKUP(C22,'DOMINGO 2'!D:AB,11,0) -> #N/A | O22: =I22-K22-L22 -> #N/A | P22: =J22-M22-N22 -> #N/A | Q22: =P22/O22 -> #N/A | R22: =VLOOKUP(C22,RANKING!E:O,9,0) -> #N/A
A23: S1 | B23: OKDINERO | C23: A0096(NATALYA PACHECO) | F23: GINA VARONI | G23: JOSE SANCHEZ | H23: =VLOOKUP(C23,'ASIGNACION RANKING'!D:AB,6,0) -> 922 | I23: =VLOOKUP(C23,'ASIGNACION RANKING'!D:AB,7,0) -> 1697048 | J23: =VLOOKUP(C23,'ASIGNACION RANKING'!D:AB,11,0) -> 144075 | K23: =VLOOKUP(C23,'DOMINGO 1'!D:AB,7,0) -> 130446 | L23: =VLOOKUP(C23,'DOMINGO 2'!D:AB,7,0) -> 105178 | M23: =VLOOKUP(C23,'DOMINGO 1'!D:AB,11,0) -> 7024 | N23: =VLOOKUP(C23,'DOMINGO 2'!D:AB,11,0) -> 7590 | O23: =I23-K23-L23 -> 1461424 | P23: =J23-M23-N23 -> 129461 | Q23: =P23/O23 -> 0.088585517 | R23: =VLOOKUP(C23,RANKING!E:O,9,0) -> B5 | S23: 30000
A24: S1 | B24: OKDINERO | C24: A0444(NICOL AMEZQUITA) | F24: GINA VARONI | G24: JOSE SANCHEZ | H24: =VLOOKUP(C24,'ASIGNACION RANKING'!D:AB,6,0) -> 844 | I24: =VLOOKUP(C24,'ASIGNACION RANKING'!D:AB,7,0) -> 1515921 | J24: =VLOOKUP(C24,'ASIGNACION RANKING'!D:AB,11,0) -> 152525 | K24: =VLOOKUP(C24,'DOMINGO 1'!D:AB,7,0) -> 124629 | L24: =VLOOKUP(C24,'DOMINGO 2'!D:AB,7,0) -> 106613 | M24: =VLOOKUP(C24,'DOMINGO 1'!D:AB,11,0) -> 9235 | N24: =VLOOKUP(C24,'DOMINGO 2'!D:AB,11,0) -> 2655 | O24: =I24-K24-L24 -> 1284679 | P24: =J24-M24-N24 -> 140635 | Q24: =P24/O24 -> 0.10947093 | R24: =VLOOKUP(C24,RANKING!E:O,9,0) -> A5
A25: S1 | B25: OKDINERO | C25: A0232(PAU ALDANA) | F25: GINA VARONI | G25: JOSE SANCHEZ | H25: =VLOOKUP(C25,'ASIGNACION RANKING'!D:AB,6,0) -> 956 | I25: =VLOOKUP(C25,'ASIGNACION RANKING'!D:AB,7,0) -> 1555092 | J25: =VLOOKUP(C25,'ASIGNACION RANKING'!D:AB,11,0) -> 123906 | K25: =VLOOKUP(C25,'DOMINGO 1'!D:AB,7,0) -> 119412 | L25: =VLOOKUP(C25,'DOMINGO 2'!D:AB,7,0) -> 116136 | M25: =VLOOKUP(C25,'DOMINGO 1'!D:AB,11,0) -> 3083 | N25: =VLOOKUP(C25,'DOMINGO 2'!D:AB,11,0) -> 8970 | O25: =I25-K25-L25 -> 1319544 | P25: =J25-M25-N25 -> 111853 | Q25: =P25/O25 -> 0.084766404 | R25: =VLOOKUP(C25,RANKING!E:O,9,0) -> B7
A26: S1 | B26: OKDINERO | C26: PAULAG08(PAULA GUTIERREZ) | F26: GINA VARONI | G26: JOSE SANCHEZ | H26: =VLOOKUP(C26,'ASIGNACION RANKING'!D:AB,6,0) -> 926 | I26: =VLOOKUP(C26,'ASIGNACION RANKING'!D:AB,7,0) -> 1789761 | J26: =VLOOKUP(C26,'ASIGNACION RANKING'!D:AB,11,0) -> 125988 | K26: =VLOOKUP(C26,'DOMINGO 1'!D:AB,7,0) -> 133250 | L26: =VLOOKUP(C26,'DOMINGO 2'!D:AB,7,0) -> 141398 | M26: =VLOOKUP(C26,'DOMINGO 1'!D:AB,11,0) -> 3159 | N26: =VLOOKUP(C26,'DOMINGO 2'!D:AB,11,0) -> 6760 | O26: =I26-K26-L26 -> 1515113 | P26: =J26-M26-N26 -> 116069 | Q26: =P26/O26 -> 0.076607487 | R26: =VLOOKUP(C26,RANKING!E:O,9,0) -> C0 | S26: 10000
A27: S1 | B27: OKDINERO | C27: A0222(PIPE GONZALEZ) | F27: GINA VARONI | G27: JOSE SANCHEZ | H27: =VLOOKUP(C27,'ASIGNACION RANKING'!D:AB,6,0) -> 965 | I27: =VLOOKUP(C27,'ASIGNACION RANKING'!D:AB,7,0) -> 1771239 | J27: =VLOOKUP(C27,'ASIGNACION RANKING'!D:AB,11,0) -> 147187 | K27: =VLOOKUP(C27,'DOMINGO 1'!D:AB,7,0) -> 143787 | L27: =VLOOKUP(C27,'DOMINGO 2'!D:AB,7,0) -> 128633 | M27: =VLOOKUP(C27,'DOMINGO 1'!D:AB,11,0) -> 7726 | N27: =VLOOKUP(C27,'DOMINGO 2'!D:AB,11,0) -> 2250 | O27: =I27-K27-L27 -> 1498819 | P27: =J27-M27-N27 -> 137211 | Q27: =P27/O27 -> 0.091546077 | R27: =VLOOKUP(C27,RANKING!E:O,9,0) -> B4
A28: S1 | B28: OKDINERO | C28: A0119(WILL) | F28: GINA VARONI | G28: JOSE SANCHEZ | H28: =VLOOKUP(C28,'ASIGNACION RANKING'!D:AB,6,0) -> 903 | I28: =VLOOKUP(C28,'ASIGNACION RANKING'!D:AB,7,0) -> 1334015 | J28: =VLOOKUP(C28,'ASIGNACION RANKING'!D:AB,11,0) -> 155833 | K28: =VLOOKUP(C28,'DOMINGO 1'!D:AB,7,0) -> 104658 | L28: =VLOOKUP(C28,'DOMINGO 2'!D:AB,7,0) -> 82610 | M28: =VLOOKUP(C28,'DOMINGO 1'!D:AB,11,0) -> 1847 | N28: =VLOOKUP(C28,'DOMINGO 2'!D:AB,11,0) -> 6305 | O28: =I28-K28-L28 -> 1146747 | P28: =J28-M28-N28 -> 147681 | Q28: =P28/O28 -> 0.12878255 | R28: =VLOOKUP(C28,RANKING!E:O,9,0) -> A2 | S28: 30000
A29: S1 | B29: OKDINERO | C29: A0438(YULI CASTRO) | F29: GINA VARONI | G29: JOSE SANCHEZ | H29: =VLOOKUP(C29,'ASIGNACION RANKING'!D:AB,6,0) -> 997 | I29: =VLOOKUP(C29,'ASIGNACION RANKING'!D:AB,7,0) -> 1888157 | J29: =VLOOKUP(C29,'ASIGNACION RANKING'!D:AB,11,0) -> 132170 | K29: =VLOOKUP(C29,'DOMINGO 1'!D:AB,7,0) -> 148717 | L29: =VLOOKUP(C29,'DOMINGO 2'!D:AB,7,0) -> 132382 | M29: =VLOOKUP(C29,'DOMINGO 1'!D:AB,11,0) -> 6216 | N29: =VLOOKUP(C29,'DOMINGO 2'!D:AB,11,0) -> 2586 | O29: =I29-K29-L29 -> 1607058 | P29: =J29-M29-N29 -> 123368 | Q29: =P29/O29 -> 0.076766364 | R29: =VLOOKUP(C29,RANKING!E:O,9,0) -> B10 | S29: 10000
A30: S2 | B30: OKDINERO | C30: A0446(ANGIE HUERTAS) | F30: GINA VARONI | G30: JOSE SANCHEZ | H30: =VLOOKUP(C30,'ASIGNACION RANKING'!D:AB,6,0) -> #N/A | I30: =VLOOKUP(C30,'ASIGNACION RANKING'!D:AB,7,0) -> #N/A | J30: =VLOOKUP(C30,'ASIGNACION RANKING'!D:AB,11,0) -> #N/A | K30: =VLOOKUP(C30,'DOMINGO 1'!D:AB,7,0) -> #N/A | L30: =VLOOKUP(C30,'DOMINGO 2'!D:AB,7,0) -> #N/A | M30: 0 | N30: 0 | O30: =I30-K30-L30 -> #N/A | P30: =J30-M30-N30 -> #N/A | Q30: =P30/O30 -> #N/A | R30: =VLOOKUP(C30,RANKING!E:O,9,0) -> #N/A
A31: S2 | B31: OKDINERO | C31: A0324(DANI P) | F31: GINA VARONI | G31: JOSE SANCHEZ | H31: =VLOOKUP(C31,'ASIGNACION RANKING'!D:AB,6,0) -> #N/A | I31: =VLOOKUP(C31,'ASIGNACION RANKING'!D:AB,7,0) -> #N/A | J31: =VLOOKUP(C31,'ASIGNACION RANKING'!D:AB,11,0) -> #N/A | K31: =VLOOKUP(C31,'DOMINGO 1'!D:AB,7,0) -> #N/A | L31: =VLOOKUP(C31,'DOMINGO 2'!D:AB,7,0) -> #N/A | M31: 0 | N31: 0 | O31: =I31-K31-L31 -> #N/A | P31: =J31-M31-N31 -> #N/A | Q31: =P31/O31 -> #N/A | R31: =VLOOKUP(C31,RANKING!E:O,9,0) -> #N/A
A32: S2 | B32: OKDINERO | C32: A0433(ESTEBAN RODRIGUEZ) | F32: GINA VARONI | G32: JOSE SANCHEZ | H32: =VLOOKUP(C32,'ASIGNACION RANKING'!D:AB,6,0) -> #N/A | I32: =VLOOKUP(C32,'ASIGNACION RANKING'!D:AB,7,0) -> #N/A | J32: =VLOOKUP(C32,'ASIGNACION RANKING'!D:AB,11,0) -> #N/A | K32: =VLOOKUP(C32,'DOMINGO 1'!D:AB,7,0) -> #N/A | L32: =VLOOKUP(C32,'DOMINGO 2'!D:AB,7,0) -> #N/A | M32: 0 | N32: 0 | O32: =I32-K32-L32 -> #N/A | P32: =J32-M32-N32 -> #N/A | Q32: =P32/O32 -> #N/A | R32: =VLOOKUP(C32,RANKING!E:O,9,0) -> #N/A
A33: S2 | B33: OKDINERO | C33: A0448(JHON VARGAS) | F33: GINA VARONI | G33: JOSE SANCHEZ | H33: =VLOOKUP(C33,'ASIGNACION RANKING'!D:AB,6,0) -> #N/A | I33: =VLOOKUP(C33,'ASIGNACION RANKING'!D:AB,7,0) -> #N/A | J33: =VLOOKUP(C33,'ASIGNACION RANKING'!D:AB,11,0) -> #N/A | K33: =VLOOKUP(C33,'DOMINGO 1'!D:AB,7,0) -> #N/A | L33: =VLOOKUP(C33,'DOMINGO 2'!D:AB,7,0) -> #N/A | M33: 0 | N33: 0 | O33: =I33-K33-L33 -> #N/A | P33: =J33-M33-N33 -> #N/A | Q33: =P33/O33 -> #N/A | R33: =VLOOKUP(C33,RANKING!E:O,9,0) -> #N/A
A34: S2 | B34: OKDINERO | C34: A0352(K MURILLO) | F34: GINA VARONI | G34: JOSE SANCHEZ | H34: =VLOOKUP(C34,'ASIGNACION RANKING'!D:AB,6,0) -> #N/A | I34: =VLOOKUP(C34,'ASIGNACION RANKING'!D:AB,7,0) -> #N/A | J34: =VLOOKUP(C34,'ASIGNACION RANKING'!D:AB,11,0) -> #N/A | K34: =VLOOKUP(C34,'DOMINGO 1'!D:AB,7,0) -> #N/A | L34: =VLOOKUP(C34,'DOMINGO 2'!D:AB,7,0) -> #N/A | M34: 0 | N34: 0 | O34: =I34-K34-L34 -> #N/A | P34: =J34-M34-N34 -> #N/A | Q34: =P34/O34 -> #N/A | R34: =VLOOKUP(C34,RANKING!E:O,9,0) -> #N/A
A35: S2 | B35: OKDINERO | C35: A0332(L AVILA) | F35: GINA VARONI | G35: JOSE SANCHEZ | H35: =VLOOKUP(C35,'ASIGNACION RANKING'!D:AB,6,0) -> #N/A | I35: =VLOOKUP(C35,'ASIGNACION RANKING'!D:AB,7,0) -> #N/A | J35: =VLOOKUP(C35,'ASIGNACION RANKING'!D:AB,11,0) -> #N/A | K35: =VLOOKUP(C35,'DOMINGO 1'!D:AB,7,0) -> #N/A | L35: =VLOOKUP(C35,'DOMINGO 2'!D:AB,7,0) -> #N/A | M35: 0 | N35: 0 | O35: =I35-K35-L35 -> #N/A | P35: =J35-M35-N35 -> #N/A | Q35: =P35/O35 -> #N/A | R35: =VLOOKUP(C35,RANKING!E:O,9,0) -> #N/A | S35: 20000
A36: S2 | B36: OKDINERO | C36: A0447(LORENA SALGADO) | F36: GINA VARONI | G36: JOSE SANCHEZ | H36: =VLOOKUP(C36,'ASIGNACION RANKING'!D:AB,6,0) -> 938 | I36: =VLOOKUP(C36,'ASIGNACION RANKING'!D:AB,7,0) -> 1737851 | J36: =VLOOKUP(C36,'ASIGNACION RANKING'!D:AB,11,0) -> 145218 | K36: =VLOOKUP(C36,'DOMINGO 1'!D:AB,7,0) -> 137639 | L36: =VLOOKUP(C36,'DOMINGO 2'!D:AB,7,0) -> 121021 | M36: 0 | N36: 0 | O36: =I36-K36-L36 -> 1479191 | P36: =J36-M36-N36 -> 145218 | Q36: =P36/O36 -> 0.098173934 | R36: =VLOOKUP(C36,RANKING!E:O,9,0) -> B5 | S36: 60000
A37: S2 | B37: OKDINERO | C37: A0140(M RAMIREZ) | F37: GINA VARONI | G37: JOSE SANCHEZ | H37: =VLOOKUP(C37,'ASIGNACION RANKING'!D:AB,6,0) -> #N/A | I37: =VLOOKUP(C37,'ASIGNACION RANKING'!D:AB,7,0) -> #N/A | J37: =VLOOKUP(C37,'ASIGNACION RANKING'!D:AB,11,0) -> #N/A | K37: =VLOOKUP(C37,'DOMINGO 1'!D:AB,7,0) -> #N/A | L37: =VLOOKUP(C37,'DOMINGO 2'!D:AB,7,0) -> #N/A | M37: 0 | N37: 0 | O37: =I37-K37-L37 -> #N/A | P37: =J37-M37-N37 -> #N/A | Q37: =P37/O37 -> #N/A | R37: =VLOOKUP(C37,RANKING!E:O,9,0) -> #N/A
A38: S2 | B38: OKDINERO | C38: A0427(MATEO DOMINGUEZ) | F38: GINA VARONI | G38: JOSE SANCHEZ | H38: =VLOOKUP(C38,'ASIGNACION RANKING'!D:AB,6,0) -> #N/A | I38: =VLOOKUP(C38,'ASIGNACION RANKING'!D:AB,7,0) -> #N/A | J38: =VLOOKUP(C38,'ASIGNACION RANKING'!D:AB,11,0) -> #N/A | K38: =VLOOKUP(C38,'DOMINGO 1'!D:AB,7,0) -> #N/A | L38: =VLOOKUP(C38,'DOMINGO 2'!D:AB,7,0) -> #N/A | M38: 0 | N38: 0 | O38: =I38-K38-L38 -> #N/A | P38: =J38-M38-N38 -> #N/A | Q38: =P38/O38 -> #N/A | R38: =VLOOKUP(C38,RANKING!E:O,9,0) -> #N/A | S38: 40000
A39: S2 | B39: OKDINERO | C39: A0205(MATEUS) | F39: GINA VARONI | G39: JOSE SANCHEZ | H39: =VLOOKUP(C39,'ASIGNACION RANKING'!D:AB,6,0) -> #N/A | I39: =VLOOKUP(C39,'ASIGNACION RANKING'!D:AB,7,0) -> #N/A | J39: =VLOOKUP(C39,'ASIGNACION RANKING'!D:AB,11,0) -> #N/A | K39: =VLOOKUP(C39,'DOMINGO 1'!D:AB,7,0) -> #N/A | L39: =VLOOKUP(C39,'DOMINGO 2'!D:AB,7,0) -> #N/A | M39: 0 | N39: 0 | O39: =I39-K39-L39 -> #N/A | P39: =J39-M39-N39 -> #N/A | Q39: =P39/O39 -> #N/A | R39: =VLOOKUP(C39,RANKING!E:O,9,0) -> #N/A
A40: S2 | B40: OKDINERO | C40: A0172(MICHEL R) | F40: GINA VARONI | G40: JOSE SANCHEZ | H40: =VLOOKUP(C40,'ASIGNACION RANKING'!D:AB,6,0) -> #N/A | I40: =VLOOKUP(C40,'ASIGNACION RANKING'!D:AB,7,0) -> #N/A | J40: =VLOOKUP(C40,'ASIGNACION RANKING'!D:AB,11,0) -> #N/A | K40: =VLOOKUP(C40,'DOMINGO 1'!D:AB,7,0) -> #N/A | L40: =VLOOKUP(C40,'DOMINGO 2'!D:AB,7,0) -> #N/A | M40: 0 | N40: 0 | O40: =I40-K40-L40 -> #N/A | P40: =J40-M40-N40 -> #N/A | Q40: =P40/O40 -> #N/A | R40: =VLOOKUP(C40,RANKING!E:O,9,0) -> #N/A
...

Sheet DATOS ASESORES
A1: NOMBRE | B1: ESTAN EN TELETRABAJO | C1: PUEDE TELETRABAJAR | D1: TIENE MOTO | E1: REGISTRO SEDE 2 | F1: Periodo de prueba | G1: Fin periodo de prueba | H1: Fecha ingreso | I1: Procesos disciplinarios
A2: Johan Sebastian Cuesta Garcia | B2: NO | C2: SI | D2: NO | E2: SI | F2: NO | H2: 45917 | I2: Descargos
A3: Laura Alejandra Velandia Martinez | B3: NO | C3: NO | D3: NO | E3: SI | F3: NO | H3: 46113 | M3: rapi s1 | N3: 13
A4: Daniel Stiven Mayorga Galindo | B4: NO | C4: SI | D4: NO | E4: SI | F4: NO | H4: 46155 | M4: rapi s2 | N4: 11
A5: Johan Sebastian Ojeda Garcia | B5: NO | D5: NO | E5: SI | F5: SI | G5: 46239 | H5: 46178 | M5: rapi m1 | N5: 7
A6: Leidy Diana Torres | B6: NO | D6: NO | E6: NO | F6: NO | H6: 46028 | I6: Descargos | J6: GRUPO 1 | M6: RAPI | N6: =SUM(N3:N5) -> 31
A7: Kevin Sebastian Murillo Avila | B7: NO | D7: NO | E7: NO | F7: SI | G7: 46266 | H7: 46204 | M7: s1 ok | N7: 13
A8: Juan Diego Melo Zuleta | B8: NO | D8: NO | E8: NO | F8: SI | G8: 46239 | H8: 46178 | M8: s2 ok | N8: 13
A9: Emilie Brigitte Alarcon Gonzalez | B9: NO | D9: NO | E9: NO | F9: NO | H9: 46158 | M9: m1 ok | N9: 8
A10: Yeison Nicolas Suarez Granados | B10: NO | C10: SI | D10: NO | E10: SI | F10: NO | H10: 45512 | M10: OK | N10: =SUM(N7:N9) -> 34
A11: Carol Tatiana Sierra Ulloa | B11: NO | C11: SI | D11: NO | E11: SI | F11: NO | H11: 46072 | M11: cash s1 | N11: 11
A12: Sandra Yuliana Huertas Perez | B12: NO | C12: NO | D12: SI | E12: SI | F12: NO | H12: 46128 | M12: cash s2 | N12: 10
A13: Jhon Jairo Alarcon Parra | B13: NO | C13: SI | D13: NO | E13: SI | F13: NO | H13: 46158 | M13: cash m1 | N13: 7
A14: Gabriela Sofia Castaño Pineda | B14: NO | C14: SI | D14: NO | E14: NO | F14: SI | G14: 46252 | H14: 46191 | M14: CASH | N14: =SUM(N11:N13) -> 28
A15: Juan Sebastian Barrios Parra | B15: NO | C15: SI | D15: NO | E15: NO | F15: NO | H15: 46137 | M15: tl jose | N15: =N6+N10+N14 -> 93
A16: Mateo Pinto Marin | B16: NO | C16: SI | D16: SI | E16: NO | F16: SI | G16: 46235 | H16: 01//06/2026
A17: Alejandro Castro Herrera | B17: NO | C17: SI | D17: SI | E17: NO | F17: NO | H17: 45932
A18: Alonso Navarro Munevar | B18: NO | C18: SI | D18: NO | E18: NO | F18: NO | H18: 46158
A19: Cristian Arley Rodriguez Lopez | B19: NO | C19: SI | D19: NO | E19: NO | F19: NO | H19: 46009
A20: Cristian David Urrego Garzon | B20: NO | C20: NO | D20: SI | E20: SI | F20: NO | H20: 46155
A21: Eddy Santiago Gomez Cabrera | B21: NO | C21: NO | D21: NO | E21: SI | F21: NO | H21: 46158 | I21: Ausencia
A22: Ingrid Dayana Huertas Perez | B22: NO | C22: SI | D22: NO | E22: SI | F22: NO | H22: 46164
A23: Jhosep Escandon Zambrano | B23: NO | C23: SI | D23: SI | E23: SI | F23: NO | H23: 46151 | I23: Ausencia
A24: John Fredy Florez Coronado | B24: NO | C24: NO | D24: NO | E24: SI | F24: NO | H24: 45962 | I24: Falta grave
A25: Jose Alejandro Vera Lopez | B25: NO | C25: SI | D25: NO | E25: NO | F25: SI | G25: 46271 | H25: 46209 | J25: GRUPO 2
A26: Manuela Cubillos Lozano | B26: NO | C26: SI | D26: NO | E26: NO | F26: NO | H26: 46155
A27: Laura Dayana Torres Carvajal | B27: NO | C27: NO | D27: NO | E27: NO | F27: NO | H27: 45885 | K27: Vacaciones 16/08/2026
A28: Nelson Andres Torres Lopez | B28: NO | C28: NO | D28: NO | E28: NO | F28: NO | H28: 46102
A29: Nesly Magyoly Sosa Ortiz | B29: NO | C29: SI | D29: NO | E29: NO | F29: NO | H29: 45952
A30: Yurany Dasney Giraldo Reyes | B30: NO | C30: NO | D30: NO | E30: NO | F30: NO | H30: 46155
A31: Andrea Juenssy Valentina Galindo | B31: NO | C31: SI | D31: SI | E31: NO | F31: SI | G31: 46244 | H31: 46183 | I31: Ausencias
A32: Daniel Leonardo Avila Lopez | B32: NO | C32: NO | D32: SI | E32: NO | F32: NO | G32: 46240 | H32: 46179
A33: Daniel Rojas Perilla | B33: NO | C33: SI | D33: NO | E33: NO | F33: SI | G33: 46244 | H33: 46183 | I33: Ausencias
A34: Fabian Estiben Arias | B34: NO | C34: SI | D34: NO | E34: NO | F34: NO | H34: 46158
A35: German Mauricio Molina Perea | B35: NO | C35: NO | D35: NO | E35: NO | F35: SI | G35: 46239 | H35: 46178 | I35: Ausencia
A36: Jasbleidy Johanna Martinez Casas | B36: NO | C36: SI | D36: NO | E36: NO | F36: SI | G36: 46235 | H36: 01//06/2026 | J36: GRUPO 3
A37: Johan Santiago Cardenas Ramirez | B37: NO | C37: SI | D37: SI | E37: NO | F37: SI | G37: 46266 | H37: 46204
A38: Juan Sebastian Ortiz Suarez | B38: NO | C38: SI | D38: NO | E38: NO | F38: NO | H38: 46155
A39: Kaffyr David Puertas Novoa | B39: NO | C39: SI | D39: NO | E39: NO | F39: SI | G39: 46252 | H39: 46191
A40: Katerinth Vanesa Vanegas Guerrero | B40: NO | C40: SI | D40: NO | E40: NO | F40: SI | G40: 46235 | H40: 01//06/2026
...

Sheet RANKING
E2: Fecha | F2: =NOW() -> 46324.461 | G2: Grupo | H2: S1 CASHMAX | J2: TLJ | K2: MATEO CANO | N2: % DEVOLUCIÓN | O2: %FALTA META | R2: https://cs.cashimax.com/indexBack
E3: RANKING COMISION | G3: ASIGNACIÓN | H3: =SUM(F5:F26) -> #N/A | I3: RECUADO | J3: RECAUDO | K3: =SUM(H5:H26) -> #N/A | N3: ='COMISION STAFF'!M3 -> #N/A | O3: ='COMISION STAFF'!N3 -> #N/A | AB3: OK S1 KATHE | AF3: OK S1 EVELIN | AJ3: OK S1 MARULANDA
E4: ASESOR | F4: Asignacion | G4: Cuentas | H4: Recaudo | I4: %_Meta | J4: % RECUPERADO | K4: TOP | N4: SIGUIENTE PISO | O4: BONO | P4: DOMINGO 1 | Q4: DOMINGO 2 | R4: DOMINGO 3 | S4: R DOMINGO 1 | T4: R DOMINGO 2 | U4: R DOMINGO 3 | V4: FESTIVO 1 | W4: R FESTIVO 1 | X4: DOMINGO 3 | AB4: ASESOR | AC4: ASIGNACION | AD4: RECAUDO | AF4: ASESOR | AG4: ASIGNACION | AH4: RECUADO | AJ4: ASESOR | AK4: ASIGNACION | AL4: RECAUDO
F5: =VLOOKUP(E5,'ASIGNACION RANKING'!D:AB,7,0) -> #N/A | G5: =VLOOKUP(E5,'ASIGNACION RANKING'!D:AB,6,0) -> #N/A | H5: =VLOOKUP(E5,'ASIGNACION RANKING'!D:AB,11,0) -> #N/A | I5: 11.12 | J5: =H5/F5 -> #N/A | K5: 1 | N5: =(H5+(H5*10%))-H5 -> #N/A | O5: 1400000 | P5: =VLOOKUP(E5,'DOMINGO 1'!D:AB,7,0) -> #N/A | Q5: =VLOOKUP(E5,'DOMINGO 2'!D:AB,7,0) -> #N/A | R5: =VLOOKUP(E5,'DOMINGO 3'!D:AB,7,0) -> #N/A | S5: =VLOOKUP(E5,'DOMINGO 1'!D:AB,11,0) -> #N/A | T5: =VLOOKUP(E5,'DOMINGO 2'!D:AB,11,0) -> #N/A | U5: =VLOOKUP(E5,'DOMINGO 3'!D:AB,11,0) -> #N/A | V5: =VLOOKUP(E5,'FESTIVO 1'!D:AB,7,0) -> #N/A | W5: =VLOOKUP(E5,'FESTIVO 1'!D:AB,11,0) -> #N/A | AB5: A0258(CRIS URREGO) | AC5: =VLOOKUP(AB5,E:O,2,0) -> 1500967 | AD5: =VLOOKUP(AB5,E:O,4,0) -> 139570 | AF5: A0144(DANIEL HERNANDEZ) | AG5: =VLOOKUP(AF5,E:O,2,0) -> 1462441 | AH5: =VLOOKUP(AF5,E:O,4,0) -> 125888 | AJ5: A0151(ALISSON CARRERO) | AK5: =VLOOKUP(AJ5,E:O,2,0) -> 1291435 | AL5: =VLOOKUP(AJ5,E:O,4,0) -> 108491
F6: =VLOOKUP(E6,'ASIGNACION RANKING'!D:AB,7,0) -> #N/A | G6: =VLOOKUP(E6,'ASIGNACION RANKING'!D:AB,6,0) -> #N/A | H6: =VLOOKUP(E6,'ASIGNACION RANKING'!D:AB,11,0) -> #N/A | I6: 16.12 | J6: =H6/F6 -> #N/A | K6: 2 | N6: =F6*J5-H6 -> #N/A | O6: 1200000 | P6: =VLOOKUP(E6,'DOMINGO 1'!D:AB,7,0) -> #N/A | Q6: =VLOOKUP(E6,'DOMINGO 2'!D:AB,7,0) -> #N/A | R6: =VLOOKUP(E6,'DOMINGO 3'!D:AB,7,0) -> #N/A | S6: =VLOOKUP(E6,'DOMINGO 1'!D:AB,11,0) -> #N/A | T6: =VLOOKUP(E6,'DOMINGO 2'!D:AB,11,0) -> #N/A | U6: =VLOOKUP(E6,'DOMINGO 3'!D:AB,11,0) -> #N/A | V6: =VLOOKUP(E6,'FESTIVO 1'!D:AB,7,0) -> #N/A | W6: =VLOOKUP(E6,'FESTIVO 1'!D:AB,11,0) -> #N/A | AB6: A0221(DAVID GOMEZ) | AC6: =VLOOKUP(AB6,E:O,2,0) -> 1452433 | AD6: =VLOOKUP(AB6,E:O,4,0) -> 144565 | AF6: A0249(DANIEL MAYORGA) | AG6: =VLOOKUP(AF6,E:O,2,0) -> 1375501 | AH6: =VLOOKUP(AF6,E:O,4,0) -> 120001 | AJ6: A0383(ALISSON MACIAS) | AK6: =VLOOKUP(AJ6,E:O,2,0) -> 1375082 | AL6: =VLOOKUP(AJ6,E:O,4,0) -> 153894
F7: =VLOOKUP(E7,'ASIGNACION RANKING'!D:AB,7,0) -> #N/A | G7: =VLOOKUP(E7,'ASIGNACION RANKING'!D:AB,6,0) -> #N/A | H7: =VLOOKUP(E7,'ASIGNACION RANKING'!D:AB,11,0) -> #N/A | J7: =H7/F7 -> #N/A | K7: 3 | N7: =F7*J6-H7 -> #N/A | O7: 1000000 | P7: =VLOOKUP(E7,'DOMINGO 1'!D:AB,7,0) -> #N/A | Q7: =VLOOKUP(E7,'DOMINGO 2'!D:AB,7,0) -> #N/A | R7: =VLOOKUP(E7,'DOMINGO 3'!D:AB,7,0) -> #N/A | S7: =VLOOKUP(E7,'DOMINGO 1'!D:AB,11,0) -> #N/A | T7: =VLOOKUP(E7,'DOMINGO 2'!D:AB,11,0) -> #N/A | U7: =VLOOKUP(E7,'DOMINGO 3'!D:AB,11,0) -> #N/A | V7: =VLOOKUP(E7,'FESTIVO 1'!D:AB,7,0) -> #N/A | W7: =VLOOKUP(E7,'FESTIVO 1'!D:AB,11,0) -> #N/A | AB7: A0288(FABIAN STIVEN) | AC7: =VLOOKUP(AB7,E:O,2,0) -> 1435695 | AD7: =VLOOKUP(AB7,E:O,4,0) -> 136800 | AF7: A0220(HEIDY AGUILAR) | AG7: =VLOOKUP(AF7,E:O,2,0) -> 855025 | AH7: =VLOOKUP(AF7,E:O,4,0) -> 56936 | AJ7: A0197(ASLE PERLAZA) | AK7: =VLOOKUP(AJ7,E:O,2,0) -> 1437376 | AL7: =VLOOKUP(AJ7,E:O,4,0) -> 140701
F8: =VLOOKUP(E8,'ASIGNACION RANKING'!D:AB,7,0) -> #N/A | G8: =VLOOKUP(E8,'ASIGNACION RANKING'!D:AB,6,0) -> #N/A | H8: =VLOOKUP(E8,'ASIGNACION RANKING'!D:AB,11,0) -> #N/A | J8: =H8/F8 -> #N/A | K8: 4 | N8: =F8*J7-H8 -> #N/A | O8: 800000 | P8: =VLOOKUP(E8,'DOMINGO 1'!D:AB,7,0) -> #N/A | Q8: =VLOOKUP(E8,'DOMINGO 2'!D:AB,7,0) -> #N/A | R8: =VLOOKUP(E8,'DOMINGO 3'!D:AB,7,0) -> #N/A | S8: =VLOOKUP(E8,'DOMINGO 1'!D:AB,11,0) -> #N/A | T8: =VLOOKUP(E8,'DOMINGO 2'!D:AB,11,0) -> #N/A | U8: =VLOOKUP(E8,'DOMINGO 3'!D:AB,11,0) -> #N/A | V8: =VLOOKUP(E8,'FESTIVO 1'!D:AB,7,0) -> #N/A | W8: =VLOOKUP(E8,'FESTIVO 1'!D:AB,11,0) -> #N/A | AB8: A0477(KAREN MARTINEZ) | AC8: =VLOOKUP(AB8,E:O,2,0) -> 259355 | AD8: =VLOOKUP(AB8,E:O,4,0) -> 15460 | AF8: A0401(HELLEN MARIN) | AG8: =VLOOKUP(AF8,E:O,2,0) -> 1245278 | AH8: =VLOOKUP(AF8,E:O,4,0) -> 116256 | AJ8: A0346(CATA TAMARA) | AK8: =VLOOKUP(AJ8,E:O,2,0) -> 1235282 | AL8: =VLOOKUP(AJ8,E:O,4,0) -> 130801
F9: =VLOOKUP(E9,'ASIGNACION RANKING'!D:AB,7,0) -> #N/A | G9: =VLOOKUP(E9,'ASIGNACION RANKING'!D:AB,6,0) -> #N/A | H9: =VLOOKUP(E9,'ASIGNACION RANKING'!D:AB,11,0) -> #N/A | J9: =H9/F9 -> #N/A | K9: 5 | N9: =F9*J8-H9 -> #N/A | O9: 600000 | P9: =VLOOKUP(E9,'DOMINGO 1'!D:AB,7,0) -> #N/A | Q9: =VLOOKUP(E9,'DOMINGO 2'!D:AB,7,0) -> #N/A | R9: =VLOOKUP(E9,'DOMINGO 3'!D:AB,7,0) -> #N/A | S9: =VLOOKUP(E9,'DOMINGO 1'!D:AB,11,0) -> #N/A | T9: =VLOOKUP(E9,'DOMINGO 2'!D:AB,11,0) -> #N/A | U9: =VLOOKUP(E9,'DOMINGO 3'!D:AB,11,0) -> #N/A | V9: =VLOOKUP(E9,'FESTIVO 1'!D:AB,7,0) -> #N/A | W9: =VLOOKUP(E9,'FESTIVO 1'!D:AB,11,0) -> #N/A | AB9: A0128(LEIDY TORRES) | AC9: =VLOOKUP(AB9,E:O,2,0) -> 1472361 | AD9: =VLOOKUP(AB9,E:O,4,0) -> 125496 | AF9: A0276(KAROLL FERNANDEZ) | AG9: =VLOOKUP(AF9,E:O,2,0) -> 1336105 | AH9: =VLOOKUP(AF9,E:O,4,0) -> 98319 | AJ9: A0161(E MACIAS) | AK9: =VLOOKUP(AJ9,E:O,2,0) -> 1383549 | AL9: =VLOOKUP(AJ9,E:O,4,0) -> 115577
F10: =VLOOKUP(E10,'ASIGNACION RANKING'!D:AB,7,0) -> #N/A | G10: =VLOOKUP(E10,'ASIGNACION RANKING'!D:AB,6,0) -> #N/A | H10: =VLOOKUP(E10,'ASIGNACION RANKING'!D:AB,11,0) -> #N/A | J10: =H10/F10 -> #N/A | K10: 6 | N10: =F10*J9-H10 -> #N/A | O10: 500000 | P10: =VLOOKUP(E10,'DOMINGO 1'!D:AB,7,0) -> #N/A | Q10: =VLOOKUP(E10,'DOMINGO 2'!D:AB,7,0) -> #N/A | R10: =VLOOKUP(E10,'DOMINGO 3'!D:AB,7,0) -> #N/A | S10: =VLOOKUP(E10,'DOMINGO 1'!D:AB,11,0) -> #N/A | T10: =VLOOKUP(E10,'DOMINGO 2'!D:AB,11,0) -> #N/A | U10: =VLOOKUP(E10,'DOMINGO 3'!D:AB,11,0) -> #N/A | V10: =VLOOKUP(E10,'FESTIVO 1'!D:AB,7,0) -> #N/A | W10: =VLOOKUP(E10,'FESTIVO 1'!D:AB,11,0) -> #N/A | AB10: A0447(LORENA SALGADO) | AC10: =VLOOKUP(AB10,E:O,2,0) -> 1479191 | AD10: =VLOOKUP(AB10,E:O,4,0) -> 132105 | AF10: A0363(Kevin Martinez) | AG10: =VLOOKUP(AF10,E:O,2,0) -> 1132129 | AH10: =VLOOKUP(AF10,E:O,4,0) -> 126847 | AJ10: A0216(JAVIER GIL) | AK10: =VLOOKUP(AJ10,E:O,2,0) -> 1507262 | AL10: =VLOOKUP(AJ10,E:O,4,0) -> 122286
F11: =VLOOKUP(E11,'ASIGNACION RANKING'!D:AB,7,0) -> #N/A | G11: =VLOOKUP(E11,'ASIGNACION RANKING'!D:AB,6,0) -> #N/A | H11: =VLOOKUP(E11,'ASIGNACION RANKING'!D:AB,11,0) -> #N/A | I11: 18.12 | J11: =H11/F11 -> #N/A | K11: 7 | N11: =F11*J10-H11 -> #N/A | O11: 400000 | P11: =VLOOKUP(E11,'DOMINGO 1'!D:AB,7,0) -> #N/A | Q11: =VLOOKUP(E11,'DOMINGO 2'!D:AB,7,0) -> #N/A | R11: =VLOOKUP(E11,'DOMINGO 3'!D:AB,7,0) -> #N/A | S11: =VLOOKUP(E11,'DOMINGO 1'!D:AB,11,0) -> #N/A | T11: =VLOOKUP(E11,'DOMINGO 2'!D:AB,11,0) -> #N/A | U11: =VLOOKUP(E11,'DOMINGO 3'!D:AB,11,0) -> #N/A | V11: =VLOOKUP(E11,'FESTIVO 1'!D:AB,7,0) -> #N/A | W11: =VLOOKUP(E11,'FESTIVO 1'!D:AB,11,0) -> #N/A | AB11: A0388(MICHAEL BARRIOS) | AC11: =VLOOKUP(AB11,E:O,2,0) -> 1739074 | AD11: =VLOOKUP(AB11,E:O,4,0) -> 118450 | AF11: A0022(Lorena Portacio) | AG11: =VLOOKUP(AF11,E:O,2,0) -> 1333664 | AH11: =VLOOKUP(AF11,E:O,4,0) -> 113219 | AJ11: A0044(JOHAN CASTILLO) | AK11: =VLOOKUP(AJ11,E:O,2,0) -> 1425071 | AL11: =VLOOKUP(AJ11,E:O,4,0) -> 137147
F12: =VLOOKUP(E12,'ASIGNACION RANKING'!D:AB,7,0) -> #N/A | G12: =VLOOKUP(E12,'ASIGNACION RANKING'!D:AB,6,0) -> #N/A | H12: =VLOOKUP(E12,'ASIGNACION RANKING'!D:AB,11,0) -> #N/A | I12: 7.12 | J12: =H12/F12 -> #N/A | K12: 8 | N12: =F12*J11-H12 -> #N/A | O12: 300000 | P12: =VLOOKUP(E12,'DOMINGO 1'!D:AB,7,0) -> #N/A | Q12: =VLOOKUP(E12,'DOMINGO 2'!D:AB,7,0) -> #N/A | R12: =VLOOKUP(E12,'DOMINGO 3'!D:AB,7,0) -> #N/A | S12: =VLOOKUP(E12,'DOMINGO 1'!D:AB,11,0) -> #N/A | T12: =VLOOKUP(E12,'DOMINGO 2'!D:AB,11,0) -> #N/A | U12: =VLOOKUP(E12,'DOMINGO 3'!D:AB,11,0) -> #N/A | V12: =VLOOKUP(E12,'FESTIVO 1'!D:AB,7,0) -> #N/A | W12: =VLOOKUP(E12,'FESTIVO 1'!D:AB,11,0) -> #N/A | AB12: A0096(NATALYA PACHECO) | AC12: =VLOOKUP(AB12,E:O,2,0) -> 1461424 | AD12: =VLOOKUP(AB12,E:O,4,0) -> 129461 | AF12: A0456(MELISSA FONQUE) | AG12: =VLOOKUP(AF12,E:O,2,0) -> 1486332 | AH12: =VLOOKUP(AF12,E:O,4,0) -> 116375 | AJ12: A0134(Jessica Fernanda Porras) | AK12: =VLOOKUP(AJ12,E:O,2,0) -> 1467542 | AL12: =VLOOKUP(AJ12,E:O,4,0) -> 129009
F13: =VLOOKUP(E13,'ASIGNACION RANKING'!D:AB,7,0) -> #N/A | G13: =VLOOKUP(E13,'ASIGNACION RANKING'!D:AB,6,0) -> #N/A | H13: =VLOOKUP(E13,'ASIGNACION RANKING'!D:AB,11,0) -> #N/A | J13: =H13/F13 -> #N/A | K13: 9 | N13: =F13*J12-H13 -> #N/A | O13: 180000 | P13: =VLOOKUP(E13,'DOMINGO 1'!D:AB,7,0) -> #N/A | Q13: =VLOOKUP(E13,'DOMINGO 2'!D:AB,7,0) -> #N/A | R13: =VLOOKUP(E13,'DOMINGO 3'!D:AB,7,0) -> #N/A | S13: =VLOOKUP(E13,'DOMINGO 1'!D:AB,11,0) -> #N/A | T13: =VLOOKUP(E13,'DOMINGO 2'!D:AB,11,0) -> #N/A | U13: =VLOOKUP(E13,'DOMINGO 3'!D:AB,11,0) -> #N/A | V13: =VLOOKUP(E13,'FESTIVO 1'!D:AB,7,0) -> #N/A | W13: =VLOOKUP(E13,'FESTIVO 1'!D:AB,11,0) -> #N/A | AB13: A0214(NEIDY FORERO ) | AC13: =VLOOKUP(AB13,E:O,2,0) -> 1387212 | AD13: =VLOOKUP(AB13,E:O,4,0) -> 112171 | AF13: A0072(MIGUEL GARCIA) | AG13: =VLOOKUP(AF13,E:O,2,0) -> 1266014 | AH13: =VLOOKUP(AF13,E:O,4,0) -> 144388 | AJ13: A0043(LAU SILVA) | AK13: =VLOOKUP(AJ13,E:O,2,0) -> 1460569 | AL13: =VLOOKUP(AJ13,E:O,4,0) -> 107350
